Watching for file changes with StatReloader
Signal handler <bound method DjangoFixup.on_import_modules of <celery.fixups.django.DjangoFixup object at 0xffffb38df160>> raised: ImportError("cannot import name 'Invoice' from 'core.models' (/app/core/models/__init__.py)")
Traceback (most recent call last):
  File "/usr/local/lib/python3.10/site-packages/celery/utils/dispatch/signal.py", line 276, in send
    response = receiver(signal=self, sender=sender, **named)
  File "/usr/local/lib/python3.10/site-packages/celery/fixups/django.py", line 100, in on_import_modules
    self.worker_fixup.validate_models()
  File "/usr/local/lib/python3.10/site-packages/celery/fixups/django.py", line 138, in validate_models
    self.django_setup()
  File "/usr/local/lib/python3.10/site-packages/celery/fixups/django.py", line 134, in django_setup
    django.setup()
  File "/usr/local/lib/python3.10/site-packages/django/__init__.py", line 24, in setup
    apps.populate(settings.INSTALLED_APPS)
  File "/usr/local/lib/python3.10/site-packages/django/apps/registry.py", line 124, in populate
    app_config.ready()
  File "/usr/local/lib/python3.10/site-packages/django/contrib/admin/apps.py", line 27, in ready
    self.module.autodiscover()
  File "/usr/local/lib/python3.10/site-packages/django/contrib/admin/__init__.py", line 50, in autodiscover
    autodiscover_modules("admin", register_to=site)
  File "/usr/local/lib/python3.10/site-packages/django/utils/module_loading.py", line 58, in autodiscover_modules
    import_module("%s.%s" % (app_config.name, module_to_search))
  File "/usr/local/lib/python3.10/importlib/__init__.py", line 126, in import_module
    return _bootstrap._gcd_import(name[level:], package, level)
  File "<frozen importlib._bootstrap>", line 1050, in _gcd_import
  File "<frozen importlib._bootstrap>", line 1027, in _find_and_load
  File "<frozen importlib._bootstrap>", line 1006, in _find_and_load_unlocked
  File "<frozen importlib._bootstrap>", line 688, in _load_unlocked
  File "<frozen importlib._bootstrap_external>", line 883, in exec_module
  File "<frozen importlib._bootstrap>", line 241, in _call_with_frames_removed
  File "/app/core/admin.py", line 2, in <module>
    from .models import (
ImportError: cannot import name 'Invoice' from 'core.models' (/app/core/models/__init__.py)
Signal handler <promise@0xffffb39500e0 --> <bound method Celery._autodiscover_tasks of <Celery enterprise_data_system at 0xffffb38dccd0>>> raised: ModuleNotFoundError("No module named 'core.ml.models.chronic_disease_model'")
Traceback (most recent call last):
  File "/usr/local/lib/python3.10/site-packages/celery/utils/dispatch/signal.py", line 276, in send
    response = receiver(signal=self, sender=sender, **named)
  File "/usr/local/lib/python3.10/site-packages/vine/promises.py", line 161, in __call__
    return self.throw()
  File "/usr/local/lib/python3.10/site-packages/vine/promises.py", line 158, in __call__
    retval = fun(*final_args, **final_kwargs)
  File "/usr/local/lib/python3.10/site-packages/celery/app/base.py", line 694, in _autodiscover_tasks
    return self._autodiscover_tasks_from_fixups(related_name)
  File "/usr/local/lib/python3.10/site-packages/celery/app/base.py", line 703, in _autodiscover_tasks_from_fixups
    return self._autodiscover_tasks_from_names([
  File "/usr/local/lib/python3.10/site-packages/celery/app/base.py", line 698, in _autodiscover_tasks_from_names
    return self.loader.autodiscover_tasks(
  File "/usr/local/lib/python3.10/site-packages/celery/loaders/base.py", line 220, in autodiscover_tasks
    mod.__name__ for mod in autodiscover_tasks(packages or (),
  File "/usr/local/lib/python3.10/site-packages/celery/loaders/base.py", line 246, in autodiscover_tasks
    return [find_related_module(pkg, related_name) for pkg in packages]
  File "/usr/local/lib/python3.10/site-packages/celery/loaders/base.py", line 246, in <listcomp>
    return [find_related_module(pkg, related_name) for pkg in packages]
  File "/usr/local/lib/python3.10/site-packages/celery/loaders/base.py", line 278, in find_related_module
    raise e
  File "/usr/local/lib/python3.10/site-packages/celery/loaders/base.py", line 270, in find_related_module
    return importlib.import_module(module_name)
  File "/usr/local/lib/python3.10/importlib/__init__.py", line 126, in import_module
    return _bootstrap._gcd_import(name[level:], package, level)
  File "<frozen importlib._bootstrap>", line 1050, in _gcd_import
  File "<frozen importlib._bootstrap>", line 1027, in _find_and_load
  File "<frozen importlib._bootstrap>", line 1006, in _find_and_load_unlocked
  File "<frozen importlib._bootstrap>", line 688, in _load_unlocked
  File "<frozen importlib._bootstrap_external>", line 883, in exec_module
  File "<frozen importlib._bootstrap>", line 241, in _call_with_frames_removed
  File "/app/core/tasks.py", line 5, in <module>
    from .ml.models.chronic_disease_model import ChronicDiseaseModel
ModuleNotFoundError: No module named 'core.ml.models.chronic_disease_model'
Watching for file changes with StatReloader
Signal handler <bound method DjangoFixup.on_import_modules of <celery.fixups.django.DjangoFixup object at 0xffff86a96b00>> raised: ImportError("cannot import name 'Invoice' from 'core.models' (/app/core/models/__init__.py)")
Traceback (most recent call last):
  File "/usr/local/lib/python3.10/site-packages/celery/utils/dispatch/signal.py", line 276, in send
    response = receiver(signal=self, sender=sender, **named)
  File "/usr/local/lib/python3.10/site-packages/celery/fixups/django.py", line 100, in on_import_modules
    self.worker_fixup.validate_models()
  File "/usr/local/lib/python3.10/site-packages/celery/fixups/django.py", line 138, in validate_models
    self.django_setup()
  File "/usr/local/lib/python3.10/site-packages/celery/fixups/django.py", line 134, in django_setup
    django.setup()
  File "/usr/local/lib/python3.10/site-packages/django/__init__.py", line 24, in setup
    apps.populate(settings.INSTALLED_APPS)
  File "/usr/local/lib/python3.10/site-packages/django/apps/registry.py", line 124, in populate
    app_config.ready()
  File "/usr/local/lib/python3.10/site-packages/django/contrib/admin/apps.py", line 27, in ready
    self.module.autodiscover()
  File "/usr/local/lib/python3.10/site-packages/django/contrib/admin/__init__.py", line 50, in autodiscover
    autodiscover_modules("admin", register_to=site)
  File "/usr/local/lib/python3.10/site-packages/django/utils/module_loading.py", line 58, in autodiscover_modules
    import_module("%s.%s" % (app_config.name, module_to_search))
  File "/usr/local/lib/python3.10/importlib/__init__.py", line 126, in import_module
    return _bootstrap._gcd_import(name[level:], package, level)
  File "<frozen importlib._bootstrap>", line 1050, in _gcd_import
  File "<frozen importlib._bootstrap>", line 1027, in _find_and_load
  File "<frozen importlib._bootstrap>", line 1006, in _find_and_load_unlocked
  File "<frozen importlib._bootstrap>", line 688, in _load_unlocked
  File "<frozen importlib._bootstrap_external>", line 883, in exec_module
  File "<frozen importlib._bootstrap>", line 241, in _call_with_frames_removed
  File "/app/core/admin.py", line 2, in <module>
    from .models import (
ImportError: cannot import name 'Invoice' from 'core.models' (/app/core/models/__init__.py)
Signal handler <promise@0xffff86b08180 --> <bound method Celery._autodiscover_tasks of <Celery enterprise_data_system at 0xffff86a94cd0>>> raised: ModuleNotFoundError("No module named 'core.ml.models.chronic_disease_model'")
Traceback (most recent call last):
  File "/usr/local/lib/python3.10/site-packages/celery/utils/dispatch/signal.py", line 276, in send
    response = receiver(signal=self, sender=sender, **named)
  File "/usr/local/lib/python3.10/site-packages/vine/promises.py", line 161, in __call__
    return self.throw()
  File "/usr/local/lib/python3.10/site-packages/vine/promises.py", line 158, in __call__
    retval = fun(*final_args, **final_kwargs)
  File "/usr/local/lib/python3.10/site-packages/celery/app/base.py", line 694, in _autodiscover_tasks
    return self._autodiscover_tasks_from_fixups(related_name)
  File "/usr/local/lib/python3.10/site-packages/celery/app/base.py", line 703, in _autodiscover_tasks_from_fixups
    return self._autodiscover_tasks_from_names([
  File "/usr/local/lib/python3.10/site-packages/celery/app/base.py", line 698, in _autodiscover_tasks_from_names
    return self.loader.autodiscover_tasks(
  File "/usr/local/lib/python3.10/site-packages/celery/loaders/base.py", line 220, in autodiscover_tasks
    mod.__name__ for mod in autodiscover_tasks(packages or (),
  File "/usr/local/lib/python3.10/site-packages/celery/loaders/base.py", line 246, in autodiscover_tasks
    return [find_related_module(pkg, related_name) for pkg in packages]
  File "/usr/local/lib/python3.10/site-packages/celery/loaders/base.py", line 246, in <listcomp>
    return [find_related_module(pkg, related_name) for pkg in packages]
  File "/usr/local/lib/python3.10/site-packages/celery/loaders/base.py", line 278, in find_related_module
    raise e
  File "/usr/local/lib/python3.10/site-packages/celery/loaders/base.py", line 270, in find_related_module
    return importlib.import_module(module_name)
  File "/usr/local/lib/python3.10/importlib/__init__.py", line 126, in import_module
    return _bootstrap._gcd_import(name[level:], package, level)
  File "<frozen importlib._bootstrap>", line 1050, in _gcd_import
  File "<frozen importlib._bootstrap>", line 1027, in _find_and_load
  File "<frozen importlib._bootstrap>", line 1006, in _find_and_load_unlocked
  File "<frozen importlib._bootstrap>", line 688, in _load_unlocked
  File "<frozen importlib._bootstrap_external>", line 883, in exec_module
  File "<frozen importlib._bootstrap>", line 241, in _call_with_frames_removed
  File "/app/core/tasks.py", line 5, in <module>
    from .ml.models.chronic_disease_model import ChronicDiseaseModel
ModuleNotFoundError: No module named 'core.ml.models.chronic_disease_model'
Watching for file changes with StatReloader
/app/core/models/__init__.py changed, reloading.
Watching for file changes with StatReloader
/app/core/models/account_models.py changed, reloading.
Watching for file changes with StatReloader
/app/enterprise_data_system/settings.py changed, reloading.
Watching for file changes with StatReloader
Watching for file changes with StatReloader
Signal handler <promise@0xffffaa3e0180 --> <bound method Celery._autodiscover_tasks of <Celery enterprise_data_system at 0xffffaa36ccd0>>> raised: ModuleNotFoundError("No module named 'core.ml.models.chronic_disease_model'")
Traceback (most recent call last):
  File "/usr/local/lib/python3.10/site-packages/celery/utils/dispatch/signal.py", line 276, in send
    response = receiver(signal=self, sender=sender, **named)
  File "/usr/local/lib/python3.10/site-packages/vine/promises.py", line 161, in __call__
    return self.throw()
  File "/usr/local/lib/python3.10/site-packages/vine/promises.py", line 158, in __call__
    retval = fun(*final_args, **final_kwargs)
  File "/usr/local/lib/python3.10/site-packages/celery/app/base.py", line 694, in _autodiscover_tasks
    return self._autodiscover_tasks_from_fixups(related_name)
  File "/usr/local/lib/python3.10/site-packages/celery/app/base.py", line 703, in _autodiscover_tasks_from_fixups
    return self._autodiscover_tasks_from_names([
  File "/usr/local/lib/python3.10/site-packages/celery/app/base.py", line 698, in _autodiscover_tasks_from_names
    return self.loader.autodiscover_tasks(
  File "/usr/local/lib/python3.10/site-packages/celery/loaders/base.py", line 220, in autodiscover_tasks
    mod.__name__ for mod in autodiscover_tasks(packages or (),
  File "/usr/local/lib/python3.10/site-packages/celery/loaders/base.py", line 246, in autodiscover_tasks
    return [find_related_module(pkg, related_name) for pkg in packages]
  File "/usr/local/lib/python3.10/site-packages/celery/loaders/base.py", line 246, in <listcomp>
    return [find_related_module(pkg, related_name) for pkg in packages]
  File "/usr/local/lib/python3.10/site-packages/celery/loaders/base.py", line 278, in find_related_module
    raise e
  File "/usr/local/lib/python3.10/site-packages/celery/loaders/base.py", line 270, in find_related_module
    return importlib.import_module(module_name)
  File "/usr/local/lib/python3.10/importlib/__init__.py", line 126, in import_module
    return _bootstrap._gcd_import(name[level:], package, level)
  File "<frozen importlib._bootstrap>", line 1050, in _gcd_import
  File "<frozen importlib._bootstrap>", line 1027, in _find_and_load
  File "<frozen importlib._bootstrap>", line 1006, in _find_and_load_unlocked
  File "<frozen importlib._bootstrap>", line 688, in _load_unlocked
  File "<frozen importlib._bootstrap_external>", line 883, in exec_module
  File "<frozen importlib._bootstrap>", line 241, in _call_with_frames_removed
  File "/app/core/tasks.py", line 5, in <module>
    from .ml.models.chronic_disease_model import ChronicDiseaseModel
ModuleNotFoundError: No module named 'core.ml.models.chronic_disease_model'
"GET /admin HTTP/1.1" 301 0
"GET /admin/ HTTP/1.1" 302 0
"GET /admin/login/?next=/admin/ HTTP/1.1" 200 4181
"GET /static/admin/css/nav_sidebar.css HTTP/1.1" 200 2694
"GET /static/admin/css/login.css HTTP/1.1" 200 958
"GET /static/admin/css/responsive.css HTTP/1.1" 200 18559
"GET /static/admin/css/base.css HTTP/1.1" 200 21310
"GET /static/admin/js/theme.js HTTP/1.1" 200 1943
"GET /static/admin/css/dark_mode.css HTTP/1.1" 200 2929
"GET /static/admin/js/nav_sidebar.js HTTP/1.1" 200 3063
Not Found: /favicon.ico
"GET /favicon.ico HTTP/1.1" 404 2339
"GET /admin HTTP/1.1" 301 0
"GET /admin/ HTTP/1.1" 302 0
"GET /admin/login/?next=/admin/ HTTP/1.1" 200 4181
"GET /static/admin/css/dark_mode.css HTTP/1.1" 200 2929
"GET /static/admin/css/login.css HTTP/1.1" 200 958
"GET /static/admin/css/nav_sidebar.css HTTP/1.1" 200 2694
"GET /static/admin/css/responsive.css HTTP/1.1" 200 18559
"GET /static/admin/css/base.css HTTP/1.1" 200 21310
"GET /static/admin/js/nav_sidebar.js HTTP/1.1" 200 3063
"GET /static/admin/js/theme.js HTTP/1.1" 200 1943
Not Found: /favicon.ico
"GET /favicon.ico HTTP/1.1" 404 2339
Forbidden: /api/customers/
"GET /api/customers/ HTTP/1.1" 403 5386
"GET /static/rest_framework/css/bootstrap-tweaks.css HTTP/1.1" 200 3426
"GET /static/rest_framework/css/prettify.css HTTP/1.1" 200 817
"GET /static/rest_framework/js/ajax-form.js HTTP/1.1" 200 3796
"GET /static/rest_framework/css/default.css HTTP/1.1" 200 1152
"GET /static/rest_framework/js/csrf.js HTTP/1.1" 200 1793
"GET /static/rest_framework/js/default.js HTTP/1.1" 200 1268
"GET /static/rest_framework/js/prettify-min.js HTTP/1.1" 200 13632
"GET /static/rest_framework/js/jquery-3.7.1.min.js HTTP/1.1" 200 87533
"GET /static/rest_framework/js/bootstrap.min.js HTTP/1.1" 200 39680
"GET /static/rest_framework/js/load-ajax-form.js HTTP/1.1" 200 59
"GET /static/rest_framework/css/bootstrap.min.css HTTP/1.1" 200 121457
"GET /static/rest_framework/img/grid.png HTTP/1.1" 200 1458
Not Found: /favicon.ico
"GET /favicon.ico HTTP/1.1" 404 2339
Watching for file changes with StatReloader
Signal handler <promise@0xffffb6910180 --> <bound method Celery._autodiscover_tasks of <Celery enterprise_data_system at 0xffffb689ccd0>>> raised: ModuleNotFoundError("No module named 'core.ml.models.chronic_disease_model'")
Traceback (most recent call last):
  File "/usr/local/lib/python3.10/site-packages/celery/utils/dispatch/signal.py", line 276, in send
    response = receiver(signal=self, sender=sender, **named)
  File "/usr/local/lib/python3.10/site-packages/vine/promises.py", line 161, in __call__
    return self.throw()
  File "/usr/local/lib/python3.10/site-packages/vine/promises.py", line 158, in __call__
    retval = fun(*final_args, **final_kwargs)
  File "/usr/local/lib/python3.10/site-packages/celery/app/base.py", line 694, in _autodiscover_tasks
    return self._autodiscover_tasks_from_fixups(related_name)
  File "/usr/local/lib/python3.10/site-packages/celery/app/base.py", line 703, in _autodiscover_tasks_from_fixups
    return self._autodiscover_tasks_from_names([
  File "/usr/local/lib/python3.10/site-packages/celery/app/base.py", line 698, in _autodiscover_tasks_from_names
    return self.loader.autodiscover_tasks(
  File "/usr/local/lib/python3.10/site-packages/celery/loaders/base.py", line 220, in autodiscover_tasks
    mod.__name__ for mod in autodiscover_tasks(packages or (),
  File "/usr/local/lib/python3.10/site-packages/celery/loaders/base.py", line 246, in autodiscover_tasks
    return [find_related_module(pkg, related_name) for pkg in packages]
  File "/usr/local/lib/python3.10/site-packages/celery/loaders/base.py", line 246, in <listcomp>
    return [find_related_module(pkg, related_name) for pkg in packages]
  File "/usr/local/lib/python3.10/site-packages/celery/loaders/base.py", line 278, in find_related_module
    raise e
  File "/usr/local/lib/python3.10/site-packages/celery/loaders/base.py", line 270, in find_related_module
    return importlib.import_module(module_name)
  File "/usr/local/lib/python3.10/importlib/__init__.py", line 126, in import_module
    return _bootstrap._gcd_import(name[level:], package, level)
  File "<frozen importlib._bootstrap>", line 1050, in _gcd_import
  File "<frozen importlib._bootstrap>", line 1027, in _find_and_load
  File "<frozen importlib._bootstrap>", line 1006, in _find_and_load_unlocked
  File "<frozen importlib._bootstrap>", line 688, in _load_unlocked
  File "<frozen importlib._bootstrap_external>", line 883, in exec_module
  File "<frozen importlib._bootstrap>", line 241, in _call_with_frames_removed
  File "/app/core/tasks.py", line 5, in <module>
    from .ml.models.chronic_disease_model import ChronicDiseaseModel
ModuleNotFoundError: No module named 'core.ml.models.chronic_disease_model'
Watching for file changes with StatReloader
Signal handler <promise@0xffff7f350180 --> <bound method Celery._autodiscover_tasks of <Celery enterprise_data_system at 0xffff7f2dccd0>>> raised: ModuleNotFoundError("No module named 'torch'")
Traceback (most recent call last):
  File "/usr/local/lib/python3.10/site-packages/celery/utils/dispatch/signal.py", line 276, in send
    response = receiver(signal=self, sender=sender, **named)
  File "/usr/local/lib/python3.10/site-packages/vine/promises.py", line 161, in __call__
    return self.throw()
  File "/usr/local/lib/python3.10/site-packages/vine/promises.py", line 158, in __call__
    retval = fun(*final_args, **final_kwargs)
  File "/usr/local/lib/python3.10/site-packages/celery/app/base.py", line 694, in _autodiscover_tasks
    return self._autodiscover_tasks_from_fixups(related_name)
  File "/usr/local/lib/python3.10/site-packages/celery/app/base.py", line 703, in _autodiscover_tasks_from_fixups
    return self._autodiscover_tasks_from_names([
  File "/usr/local/lib/python3.10/site-packages/celery/app/base.py", line 698, in _autodiscover_tasks_from_names
    return self.loader.autodiscover_tasks(
  File "/usr/local/lib/python3.10/site-packages/celery/loaders/base.py", line 220, in autodiscover_tasks
    mod.__name__ for mod in autodiscover_tasks(packages or (),
  File "/usr/local/lib/python3.10/site-packages/celery/loaders/base.py", line 246, in autodiscover_tasks
    return [find_related_module(pkg, related_name) for pkg in packages]
  File "/usr/local/lib/python3.10/site-packages/celery/loaders/base.py", line 246, in <listcomp>
    return [find_related_module(pkg, related_name) for pkg in packages]
  File "/usr/local/lib/python3.10/site-packages/celery/loaders/base.py", line 278, in find_related_module
    raise e
  File "/usr/local/lib/python3.10/site-packages/celery/loaders/base.py", line 270, in find_related_module
    return importlib.import_module(module_name)
  File "/usr/local/lib/python3.10/importlib/__init__.py", line 126, in import_module
    return _bootstrap._gcd_import(name[level:], package, level)
  File "<frozen importlib._bootstrap>", line 1050, in _gcd_import
  File "<frozen importlib._bootstrap>", line 1027, in _find_and_load
  File "<frozen importlib._bootstrap>", line 1006, in _find_and_load_unlocked
  File "<frozen importlib._bootstrap>", line 688, in _load_unlocked
  File "<frozen importlib._bootstrap_external>", line 883, in exec_module
  File "<frozen importlib._bootstrap>", line 241, in _call_with_frames_removed
  File "/app/core/tasks.py", line 5, in <module>
    from .ml.models.chronic_disease_model import ChronicDiseaseModel
  File "/app/core/ml/models/chronic_disease_model.py", line 4, in <module>
    from .base_model import BaseModel
  File "/app/core/ml/models/base_model.py", line 8, in <module>
    import torch
ModuleNotFoundError: No module named 'torch'
Watching for file changes with StatReloader
Signal handler <promise@0xffffa8164180 --> <bound method Celery._autodiscover_tasks of <Celery enterprise_data_system at 0xffffa80ecee0>>> raised: ImportError("cannot import name 'ChronicDiseaseModel' from 'core.ml.models.chronic_disease_model' (/app/core/ml/models/chronic_disease_model.py)")
Traceback (most recent call last):
  File "/usr/local/lib/python3.10/site-packages/celery/utils/dispatch/signal.py", line 276, in send
    response = receiver(signal=self, sender=sender, **named)
  File "/usr/local/lib/python3.10/site-packages/vine/promises.py", line 161, in __call__
    return self.throw()
  File "/usr/local/lib/python3.10/site-packages/vine/promises.py", line 158, in __call__
    retval = fun(*final_args, **final_kwargs)
  File "/usr/local/lib/python3.10/site-packages/celery/app/base.py", line 694, in _autodiscover_tasks
    return self._autodiscover_tasks_from_fixups(related_name)
  File "/usr/local/lib/python3.10/site-packages/celery/app/base.py", line 703, in _autodiscover_tasks_from_fixups
    return self._autodiscover_tasks_from_names([
  File "/usr/local/lib/python3.10/site-packages/celery/app/base.py", line 698, in _autodiscover_tasks_from_names
    return self.loader.autodiscover_tasks(
  File "/usr/local/lib/python3.10/site-packages/celery/loaders/base.py", line 220, in autodiscover_tasks
    mod.__name__ for mod in autodiscover_tasks(packages or (),
  File "/usr/local/lib/python3.10/site-packages/celery/loaders/base.py", line 246, in autodiscover_tasks
    return [find_related_module(pkg, related_name) for pkg in packages]
  File "/usr/local/lib/python3.10/site-packages/celery/loaders/base.py", line 246, in <listcomp>
    return [find_related_module(pkg, related_name) for pkg in packages]
  File "/usr/local/lib/python3.10/site-packages/celery/loaders/base.py", line 270, in find_related_module
    return importlib.import_module(module_name)
  File "/usr/local/lib/python3.10/importlib/__init__.py", line 126, in import_module
    return _bootstrap._gcd_import(name[level:], package, level)
  File "<frozen importlib._bootstrap>", line 1050, in _gcd_import
  File "<frozen importlib._bootstrap>", line 1027, in _find_and_load
  File "<frozen importlib._bootstrap>", line 1006, in _find_and_load_unlocked
  File "<frozen importlib._bootstrap>", line 688, in _load_unlocked
  File "<frozen importlib._bootstrap_external>", line 883, in exec_module
  File "<frozen importlib._bootstrap>", line 241, in _call_with_frames_removed
  File "/app/core/tasks.py", line 5, in <module>
    from .ml.models.chronic_disease_model import ChronicDiseaseModel
ImportError: cannot import name 'ChronicDiseaseModel' from 'core.ml.models.chronic_disease_model' (/app/core/ml/models/chronic_disease_model.py)
Watching for file changes with StatReloader
Signal handler <promise@0xffff8806c180 --> <bound method Celery._autodiscover_tasks of <Celery enterprise_data_system at 0xffff87ff4ee0>>> raised: ImportError("cannot import name 'ChronicDiseaseModel' from 'core.ml.models.chronic_disease_model' (/app/core/ml/models/chronic_disease_model.py)")
Traceback (most recent call last):
  File "/usr/local/lib/python3.10/site-packages/celery/utils/dispatch/signal.py", line 276, in send
    response = receiver(signal=self, sender=sender, **named)
  File "/usr/local/lib/python3.10/site-packages/vine/promises.py", line 161, in __call__
    return self.throw()
  File "/usr/local/lib/python3.10/site-packages/vine/promises.py", line 158, in __call__
    retval = fun(*final_args, **final_kwargs)
  File "/usr/local/lib/python3.10/site-packages/celery/app/base.py", line 694, in _autodiscover_tasks
    return self._autodiscover_tasks_from_fixups(related_name)
  File "/usr/local/lib/python3.10/site-packages/celery/app/base.py", line 703, in _autodiscover_tasks_from_fixups
    return self._autodiscover_tasks_from_names([
  File "/usr/local/lib/python3.10/site-packages/celery/app/base.py", line 698, in _autodiscover_tasks_from_names
    return self.loader.autodiscover_tasks(
  File "/usr/local/lib/python3.10/site-packages/celery/loaders/base.py", line 220, in autodiscover_tasks
    mod.__name__ for mod in autodiscover_tasks(packages or (),
  File "/usr/local/lib/python3.10/site-packages/celery/loaders/base.py", line 246, in autodiscover_tasks
    return [find_related_module(pkg, related_name) for pkg in packages]
  File "/usr/local/lib/python3.10/site-packages/celery/loaders/base.py", line 246, in <listcomp>
    return [find_related_module(pkg, related_name) for pkg in packages]
  File "/usr/local/lib/python3.10/site-packages/celery/loaders/base.py", line 270, in find_related_module
    return importlib.import_module(module_name)
  File "/usr/local/lib/python3.10/importlib/__init__.py", line 126, in import_module
    return _bootstrap._gcd_import(name[level:], package, level)
  File "<frozen importlib._bootstrap>", line 1050, in _gcd_import
  File "<frozen importlib._bootstrap>", line 1027, in _find_and_load
  File "<frozen importlib._bootstrap>", line 1006, in _find_and_load_unlocked
  File "<frozen importlib._bootstrap>", line 688, in _load_unlocked
  File "<frozen importlib._bootstrap_external>", line 883, in exec_module
  File "<frozen importlib._bootstrap>", line 241, in _call_with_frames_removed
  File "/app/core/tasks.py", line 5, in <module>
    from .ml.models.chronic_disease_model import ChronicDiseaseModel
ImportError: cannot import name 'ChronicDiseaseModel' from 'core.ml.models.chronic_disease_model' (/app/core/ml/models/chronic_disease_model.py)
Signal handler <promise@0xffff81af4b80 --> <bound method Celery._autodiscover_tasks of <Celery enterprise_data_system at 0xffff81abd120>>> raised: ImportError("cannot import name 'ChronicDiseaseModel' from 'core.ml.models.chronic_disease_model' (/app/core/ml/models/chronic_disease_model.py)")
Traceback (most recent call last):
  File "/usr/local/lib/python3.10/site-packages/celery/utils/dispatch/signal.py", line 276, in send
    response = receiver(signal=self, sender=sender, **named)
  File "/usr/local/lib/python3.10/site-packages/vine/promises.py", line 161, in __call__
    return self.throw()
  File "/usr/local/lib/python3.10/site-packages/vine/promises.py", line 158, in __call__
    retval = fun(*final_args, **final_kwargs)
  File "/usr/local/lib/python3.10/site-packages/celery/app/base.py", line 694, in _autodiscover_tasks
    return self._autodiscover_tasks_from_fixups(related_name)
  File "/usr/local/lib/python3.10/site-packages/celery/app/base.py", line 703, in _autodiscover_tasks_from_fixups
    return self._autodiscover_tasks_from_names([
  File "/usr/local/lib/python3.10/site-packages/celery/app/base.py", line 698, in _autodiscover_tasks_from_names
    return self.loader.autodiscover_tasks(
  File "/usr/local/lib/python3.10/site-packages/celery/loaders/base.py", line 220, in autodiscover_tasks
    mod.__name__ for mod in autodiscover_tasks(packages or (),
  File "/usr/local/lib/python3.10/site-packages/celery/loaders/base.py", line 246, in autodiscover_tasks
    return [find_related_module(pkg, related_name) for pkg in packages]
  File "/usr/local/lib/python3.10/site-packages/celery/loaders/base.py", line 246, in <listcomp>
    return [find_related_module(pkg, related_name) for pkg in packages]
  File "/usr/local/lib/python3.10/site-packages/celery/loaders/base.py", line 270, in find_related_module
    return importlib.import_module(module_name)
  File "/usr/local/lib/python3.10/importlib/__init__.py", line 126, in import_module
    return _bootstrap._gcd_import(name[level:], package, level)
  File "<frozen importlib._bootstrap>", line 1050, in _gcd_import
  File "<frozen importlib._bootstrap>", line 1027, in _find_and_load
  File "<frozen importlib._bootstrap>", line 1006, in _find_and_load_unlocked
  File "<frozen importlib._bootstrap>", line 688, in _load_unlocked
  File "<frozen importlib._bootstrap_external>", line 883, in exec_module
  File "<frozen importlib._bootstrap>", line 241, in _call_with_frames_removed
  File "/app/core/tasks.py", line 5, in <module>
    from .ml.models.chronic_disease_model import ChronicDiseaseModel
ImportError: cannot import name 'ChronicDiseaseModel' from 'core.ml.models.chronic_disease_model' (/app/core/ml/models/chronic_disease_model.py)
Signal handler <promise@0xffff83b6cb80 --> <bound method Celery._autodiscover_tasks of <Celery enterprise_data_system at 0xffff83b35120>>> raised: ImportError("cannot import name 'ChurnPredictionModel' from 'core.ml.models.churn_prediction_model' (/app/core/ml/models/churn_prediction_model.py)")
Traceback (most recent call last):
  File "/usr/local/lib/python3.10/site-packages/celery/utils/dispatch/signal.py", line 276, in send
    response = receiver(signal=self, sender=sender, **named)
  File "/usr/local/lib/python3.10/site-packages/vine/promises.py", line 161, in __call__
    return self.throw()
  File "/usr/local/lib/python3.10/site-packages/vine/promises.py", line 158, in __call__
    retval = fun(*final_args, **final_kwargs)
  File "/usr/local/lib/python3.10/site-packages/celery/app/base.py", line 694, in _autodiscover_tasks
    return self._autodiscover_tasks_from_fixups(related_name)
  File "/usr/local/lib/python3.10/site-packages/celery/app/base.py", line 703, in _autodiscover_tasks_from_fixups
    return self._autodiscover_tasks_from_names([
  File "/usr/local/lib/python3.10/site-packages/celery/app/base.py", line 698, in _autodiscover_tasks_from_names
    return self.loader.autodiscover_tasks(
  File "/usr/local/lib/python3.10/site-packages/celery/loaders/base.py", line 220, in autodiscover_tasks
    mod.__name__ for mod in autodiscover_tasks(packages or (),
  File "/usr/local/lib/python3.10/site-packages/celery/loaders/base.py", line 246, in autodiscover_tasks
    return [find_related_module(pkg, related_name) for pkg in packages]
  File "/usr/local/lib/python3.10/site-packages/celery/loaders/base.py", line 246, in <listcomp>
    return [find_related_module(pkg, related_name) for pkg in packages]
  File "/usr/local/lib/python3.10/site-packages/celery/loaders/base.py", line 270, in find_related_module
    return importlib.import_module(module_name)
  File "/usr/local/lib/python3.10/importlib/__init__.py", line 126, in import_module
    return _bootstrap._gcd_import(name[level:], package, level)
  File "<frozen importlib._bootstrap>", line 1050, in _gcd_import
  File "<frozen importlib._bootstrap>", line 1027, in _find_and_load
  File "<frozen importlib._bootstrap>", line 1006, in _find_and_load_unlocked
  File "<frozen importlib._bootstrap>", line 688, in _load_unlocked
  File "<frozen importlib._bootstrap_external>", line 883, in exec_module
  File "<frozen importlib._bootstrap>", line 241, in _call_with_frames_removed
  File "/app/core/tasks.py", line 6, in <module>
    from .ml.models.churn_prediction_model import ChurnPredictionModel
ImportError: cannot import name 'ChurnPredictionModel' from 'core.ml.models.churn_prediction_model' (/app/core/ml/models/churn_prediction_model.py)
Watching for file changes with StatReloader
Watching for file changes with StatReloader
Watching for file changes with StatReloader
Watching for file changes with StatReloader
