Watching for file changes with StatReloader
Signal handler <bound method DjangoFixup.on_import_modules of <celery.fixups.django.DjangoFixup object at 0xffffb38df160>> raised: ImportError("cannot import name 'Invoice' from 'core.models' (/app/core/models/__init__.py)")
Traceback (most recent call last):
  File "/usr/local/lib/python3.10/site-packages/celery/utils/dispatch/signal.py", line 276, in send
    response = receiver(signal=self, sender=sender, **named)
  File "/usr/local/lib/python3.10/site-packages/celery/fixups/django.py", line 100, in on_import_modules
    self.worker_fixup.validate_models()
  File "/usr/local/lib/python3.10/site-packages/celery/fixups/django.py", line 138, in validate_models
    self.django_setup()
  File "/usr/local/lib/python3.10/site-packages/celery/fixups/django.py", line 134, in django_setup
    django.setup()
  File "/usr/local/lib/python3.10/site-packages/django/__init__.py", line 24, in setup
    apps.populate(settings.INSTALLED_APPS)
  File "/usr/local/lib/python3.10/site-packages/django/apps/registry.py", line 124, in populate
    app_config.ready()
  File "/usr/local/lib/python3.10/site-packages/django/contrib/admin/apps.py", line 27, in ready
    self.module.autodiscover()
  File "/usr/local/lib/python3.10/site-packages/django/contrib/admin/__init__.py", line 50, in autodiscover
    autodiscover_modules("admin", register_to=site)
  File "/usr/local/lib/python3.10/site-packages/django/utils/module_loading.py", line 58, in autodiscover_modules
    import_module("%s.%s" % (app_config.name, module_to_search))
  File "/usr/local/lib/python3.10/importlib/__init__.py", line 126, in import_module
    return _bootstrap._gcd_import(name[level:], package, level)
  File "<frozen importlib._bootstrap>", line 1050, in _gcd_import
  File "<frozen importlib._bootstrap>", line 1027, in _find_and_load
  File "<frozen importlib._bootstrap>", line 1006, in _find_and_load_unlocked
  File "<frozen importlib._bootstrap>", line 688, in _load_unlocked
  File "<frozen importlib._bootstrap_external>", line 883, in exec_module
  File "<frozen importlib._bootstrap>", line 241, in _call_with_frames_removed
  File "/app/core/admin.py", line 2, in <module>
    from .models import (
ImportError: cannot import name 'Invoice' from 'core.models' (/app/core/models/__init__.py)
Signal handler <promise@0xffffb39500e0 --> <bound method Celery._autodiscover_tasks of <Celery enterprise_data_system at 0xffffb38dccd0>>> raised: ModuleNotFoundError("No module named 'core.ml.models.chronic_disease_model'")
Traceback (most recent call last):
  File "/usr/local/lib/python3.10/site-packages/celery/utils/dispatch/signal.py", line 276, in send
    response = receiver(signal=self, sender=sender, **named)
  File "/usr/local/lib/python3.10/site-packages/vine/promises.py", line 161, in __call__
    return self.throw()
  File "/usr/local/lib/python3.10/site-packages/vine/promises.py", line 158, in __call__
    retval = fun(*final_args, **final_kwargs)
  File "/usr/local/lib/python3.10/site-packages/celery/app/base.py", line 694, in _autodiscover_tasks
    return self._autodiscover_tasks_from_fixups(related_name)
  File "/usr/local/lib/python3.10/site-packages/celery/app/base.py", line 703, in _autodiscover_tasks_from_fixups
    return self._autodiscover_tasks_from_names([
  File "/usr/local/lib/python3.10/site-packages/celery/app/base.py", line 698, in _autodiscover_tasks_from_names
    return self.loader.autodiscover_tasks(
  File "/usr/local/lib/python3.10/site-packages/celery/loaders/base.py", line 220, in autodiscover_tasks
    mod.__name__ for mod in autodiscover_tasks(packages or (),
  File "/usr/local/lib/python3.10/site-packages/celery/loaders/base.py", line 246, in autodiscover_tasks
    return [find_related_module(pkg, related_name) for pkg in packages]
  File "/usr/local/lib/python3.10/site-packages/celery/loaders/base.py", line 246, in <listcomp>
    return [find_related_module(pkg, related_name) for pkg in packages]
  File "/usr/local/lib/python3.10/site-packages/celery/loaders/base.py", line 278, in find_related_module
    raise e
  File "/usr/local/lib/python3.10/site-packages/celery/loaders/base.py", line 270, in find_related_module
    return importlib.import_module(module_name)
  File "/usr/local/lib/python3.10/importlib/__init__.py", line 126, in import_module
    return _bootstrap._gcd_import(name[level:], package, level)
  File "<frozen importlib._bootstrap>", line 1050, in _gcd_import
  File "<frozen importlib._bootstrap>", line 1027, in _find_and_load
  File "<frozen importlib._bootstrap>", line 1006, in _find_and_load_unlocked
  File "<frozen importlib._bootstrap>", line 688, in _load_unlocked
  File "<frozen importlib._bootstrap_external>", line 883, in exec_module
  File "<frozen importlib._bootstrap>", line 241, in _call_with_frames_removed
  File "/app/core/tasks.py", line 5, in <module>
    from .ml.models.chronic_disease_model import ChronicDiseaseModel
ModuleNotFoundError: No module named 'core.ml.models.chronic_disease_model'
Watching for file changes with StatReloader
Signal handler <bound method DjangoFixup.on_import_modules of <celery.fixups.django.DjangoFixup object at 0xffff86a96b00>> raised: ImportError("cannot import name 'Invoice' from 'core.models' (/app/core/models/__init__.py)")
Traceback (most recent call last):
  File "/usr/local/lib/python3.10/site-packages/celery/utils/dispatch/signal.py", line 276, in send
    response = receiver(signal=self, sender=sender, **named)
  File "/usr/local/lib/python3.10/site-packages/celery/fixups/django.py", line 100, in on_import_modules
    self.worker_fixup.validate_models()
  File "/usr/local/lib/python3.10/site-packages/celery/fixups/django.py", line 138, in validate_models
    self.django_setup()
  File "/usr/local/lib/python3.10/site-packages/celery/fixups/django.py", line 134, in django_setup
    django.setup()
  File "/usr/local/lib/python3.10/site-packages/django/__init__.py", line 24, in setup
    apps.populate(settings.INSTALLED_APPS)
  File "/usr/local/lib/python3.10/site-packages/django/apps/registry.py", line 124, in populate
    app_config.ready()
  File "/usr/local/lib/python3.10/site-packages/django/contrib/admin/apps.py", line 27, in ready
    self.module.autodiscover()
  File "/usr/local/lib/python3.10/site-packages/django/contrib/admin/__init__.py", line 50, in autodiscover
    autodiscover_modules("admin", register_to=site)
  File "/usr/local/lib/python3.10/site-packages/django/utils/module_loading.py", line 58, in autodiscover_modules
    import_module("%s.%s" % (app_config.name, module_to_search))
  File "/usr/local/lib/python3.10/importlib/__init__.py", line 126, in import_module
    return _bootstrap._gcd_import(name[level:], package, level)
  File "<frozen importlib._bootstrap>", line 1050, in _gcd_import
  File "<frozen importlib._bootstrap>", line 1027, in _find_and_load
  File "<frozen importlib._bootstrap>", line 1006, in _find_and_load_unlocked
  File "<frozen importlib._bootstrap>", line 688, in _load_unlocked
  File "<frozen importlib._bootstrap_external>", line 883, in exec_module
  File "<frozen importlib._bootstrap>", line 241, in _call_with_frames_removed
  File "/app/core/admin.py", line 2, in <module>
    from .models import (
ImportError: cannot import name 'Invoice' from 'core.models' (/app/core/models/__init__.py)
Signal handler <promise@0xffff86b08180 --> <bound method Celery._autodiscover_tasks of <Celery enterprise_data_system at 0xffff86a94cd0>>> raised: ModuleNotFoundError("No module named 'core.ml.models.chronic_disease_model'")
Traceback (most recent call last):
  File "/usr/local/lib/python3.10/site-packages/celery/utils/dispatch/signal.py", line 276, in send
    response = receiver(signal=self, sender=sender, **named)
  File "/usr/local/lib/python3.10/site-packages/vine/promises.py", line 161, in __call__
    return self.throw()
  File "/usr/local/lib/python3.10/site-packages/vine/promises.py", line 158, in __call__
    retval = fun(*final_args, **final_kwargs)
  File "/usr/local/lib/python3.10/site-packages/celery/app/base.py", line 694, in _autodiscover_tasks
    return self._autodiscover_tasks_from_fixups(related_name)
  File "/usr/local/lib/python3.10/site-packages/celery/app/base.py", line 703, in _autodiscover_tasks_from_fixups
    return self._autodiscover_tasks_from_names([
  File "/usr/local/lib/python3.10/site-packages/celery/app/base.py", line 698, in _autodiscover_tasks_from_names
    return self.loader.autodiscover_tasks(
  File "/usr/local/lib/python3.10/site-packages/celery/loaders/base.py", line 220, in autodiscover_tasks
    mod.__name__ for mod in autodiscover_tasks(packages or (),
  File "/usr/local/lib/python3.10/site-packages/celery/loaders/base.py", line 246, in autodiscover_tasks
    return [find_related_module(pkg, related_name) for pkg in packages]
  File "/usr/local/lib/python3.10/site-packages/celery/loaders/base.py", line 246, in <listcomp>
    return [find_related_module(pkg, related_name) for pkg in packages]
  File "/usr/local/lib/python3.10/site-packages/celery/loaders/base.py", line 278, in find_related_module
    raise e
  File "/usr/local/lib/python3.10/site-packages/celery/loaders/base.py", line 270, in find_related_module
    return importlib.import_module(module_name)
  File "/usr/local/lib/python3.10/importlib/__init__.py", line 126, in import_module
    return _bootstrap._gcd_import(name[level:], package, level)
  File "<frozen importlib._bootstrap>", line 1050, in _gcd_import
  File "<frozen importlib._bootstrap>", line 1027, in _find_and_load
  File "<frozen importlib._bootstrap>", line 1006, in _find_and_load_unlocked
  File "<frozen importlib._bootstrap>", line 688, in _load_unlocked
  File "<frozen importlib._bootstrap_external>", line 883, in exec_module
  File "<frozen importlib._bootstrap>", line 241, in _call_with_frames_removed
  File "/app/core/tasks.py", line 5, in <module>
    from .ml.models.chronic_disease_model import ChronicDiseaseModel
ModuleNotFoundError: No module named 'core.ml.models.chronic_disease_model'
Watching for file changes with StatReloader
/app/core/models/__init__.py changed, reloading.
Watching for file changes with StatReloader
/app/core/models/account_models.py changed, reloading.
Watching for file changes with StatReloader
/app/enterprise_data_system/settings.py changed, reloading.
Watching for file changes with StatReloader
Watching for file changes with StatReloader
Signal handler <promise@0xffffaa3e0180 --> <bound method Celery._autodiscover_tasks of <Celery enterprise_data_system at 0xffffaa36ccd0>>> raised: ModuleNotFoundError("No module named 'core.ml.models.chronic_disease_model'")
Traceback (most recent call last):
  File "/usr/local/lib/python3.10/site-packages/celery/utils/dispatch/signal.py", line 276, in send
    response = receiver(signal=self, sender=sender, **named)
  File "/usr/local/lib/python3.10/site-packages/vine/promises.py", line 161, in __call__
    return self.throw()
  File "/usr/local/lib/python3.10/site-packages/vine/promises.py", line 158, in __call__
    retval = fun(*final_args, **final_kwargs)
  File "/usr/local/lib/python3.10/site-packages/celery/app/base.py", line 694, in _autodiscover_tasks
    return self._autodiscover_tasks_from_fixups(related_name)
  File "/usr/local/lib/python3.10/site-packages/celery/app/base.py", line 703, in _autodiscover_tasks_from_fixups
    return self._autodiscover_tasks_from_names([
  File "/usr/local/lib/python3.10/site-packages/celery/app/base.py", line 698, in _autodiscover_tasks_from_names
    return self.loader.autodiscover_tasks(
  File "/usr/local/lib/python3.10/site-packages/celery/loaders/base.py", line 220, in autodiscover_tasks
    mod.__name__ for mod in autodiscover_tasks(packages or (),
  File "/usr/local/lib/python3.10/site-packages/celery/loaders/base.py", line 246, in autodiscover_tasks
    return [find_related_module(pkg, related_name) for pkg in packages]
  File "/usr/local/lib/python3.10/site-packages/celery/loaders/base.py", line 246, in <listcomp>
    return [find_related_module(pkg, related_name) for pkg in packages]
  File "/usr/local/lib/python3.10/site-packages/celery/loaders/base.py", line 278, in find_related_module
    raise e
  File "/usr/local/lib/python3.10/site-packages/celery/loaders/base.py", line 270, in find_related_module
    return importlib.import_module(module_name)
  File "/usr/local/lib/python3.10/importlib/__init__.py", line 126, in import_module
    return _bootstrap._gcd_import(name[level:], package, level)
  File "<frozen importlib._bootstrap>", line 1050, in _gcd_import
  File "<frozen importlib._bootstrap>", line 1027, in _find_and_load
  File "<frozen importlib._bootstrap>", line 1006, in _find_and_load_unlocked
  File "<frozen importlib._bootstrap>", line 688, in _load_unlocked
  File "<frozen importlib._bootstrap_external>", line 883, in exec_module
  File "<frozen importlib._bootstrap>", line 241, in _call_with_frames_removed
  File "/app/core/tasks.py", line 5, in <module>
    from .ml.models.chronic_disease_model import ChronicDiseaseModel
ModuleNotFoundError: No module named 'core.ml.models.chronic_disease_model'
"GET /admin HTTP/1.1" 301 0
"GET /admin/ HTTP/1.1" 302 0
"GET /admin/login/?next=/admin/ HTTP/1.1" 200 4181
"GET /static/admin/css/nav_sidebar.css HTTP/1.1" 200 2694
"GET /static/admin/css/login.css HTTP/1.1" 200 958
"GET /static/admin/css/responsive.css HTTP/1.1" 200 18559
"GET /static/admin/css/base.css HTTP/1.1" 200 21310
"GET /static/admin/js/theme.js HTTP/1.1" 200 1943
"GET /static/admin/css/dark_mode.css HTTP/1.1" 200 2929
"GET /static/admin/js/nav_sidebar.js HTTP/1.1" 200 3063
Not Found: /favicon.ico
"GET /favicon.ico HTTP/1.1" 404 2339
"GET /admin HTTP/1.1" 301 0
"GET /admin/ HTTP/1.1" 302 0
"GET /admin/login/?next=/admin/ HTTP/1.1" 200 4181
"GET /static/admin/css/dark_mode.css HTTP/1.1" 200 2929
"GET /static/admin/css/login.css HTTP/1.1" 200 958
"GET /static/admin/css/nav_sidebar.css HTTP/1.1" 200 2694
"GET /static/admin/css/responsive.css HTTP/1.1" 200 18559
"GET /static/admin/css/base.css HTTP/1.1" 200 21310
"GET /static/admin/js/nav_sidebar.js HTTP/1.1" 200 3063
"GET /static/admin/js/theme.js HTTP/1.1" 200 1943
Not Found: /favicon.ico
"GET /favicon.ico HTTP/1.1" 404 2339
Forbidden: /api/customers/
"GET /api/customers/ HTTP/1.1" 403 5386
"GET /static/rest_framework/css/bootstrap-tweaks.css HTTP/1.1" 200 3426
"GET /static/rest_framework/css/prettify.css HTTP/1.1" 200 817
"GET /static/rest_framework/js/ajax-form.js HTTP/1.1" 200 3796
"GET /static/rest_framework/css/default.css HTTP/1.1" 200 1152
"GET /static/rest_framework/js/csrf.js HTTP/1.1" 200 1793
"GET /static/rest_framework/js/default.js HTTP/1.1" 200 1268
"GET /static/rest_framework/js/prettify-min.js HTTP/1.1" 200 13632
"GET /static/rest_framework/js/jquery-3.7.1.min.js HTTP/1.1" 200 87533
"GET /static/rest_framework/js/bootstrap.min.js HTTP/1.1" 200 39680
"GET /static/rest_framework/js/load-ajax-form.js HTTP/1.1" 200 59
"GET /static/rest_framework/css/bootstrap.min.css HTTP/1.1" 200 121457
"GET /static/rest_framework/img/grid.png HTTP/1.1" 200 1458
Not Found: /favicon.ico
"GET /favicon.ico HTTP/1.1" 404 2339
Watching for file changes with StatReloader
Signal handler <promise@0xffffb6910180 --> <bound method Celery._autodiscover_tasks of <Celery enterprise_data_system at 0xffffb689ccd0>>> raised: ModuleNotFoundError("No module named 'core.ml.models.chronic_disease_model'")
Traceback (most recent call last):
  File "/usr/local/lib/python3.10/site-packages/celery/utils/dispatch/signal.py", line 276, in send
    response = receiver(signal=self, sender=sender, **named)
  File "/usr/local/lib/python3.10/site-packages/vine/promises.py", line 161, in __call__
    return self.throw()
  File "/usr/local/lib/python3.10/site-packages/vine/promises.py", line 158, in __call__
    retval = fun(*final_args, **final_kwargs)
  File "/usr/local/lib/python3.10/site-packages/celery/app/base.py", line 694, in _autodiscover_tasks
    return self._autodiscover_tasks_from_fixups(related_name)
  File "/usr/local/lib/python3.10/site-packages/celery/app/base.py", line 703, in _autodiscover_tasks_from_fixups
    return self._autodiscover_tasks_from_names([
  File "/usr/local/lib/python3.10/site-packages/celery/app/base.py", line 698, in _autodiscover_tasks_from_names
    return self.loader.autodiscover_tasks(
  File "/usr/local/lib/python3.10/site-packages/celery/loaders/base.py", line 220, in autodiscover_tasks
    mod.__name__ for mod in autodiscover_tasks(packages or (),
  File "/usr/local/lib/python3.10/site-packages/celery/loaders/base.py", line 246, in autodiscover_tasks
    return [find_related_module(pkg, related_name) for pkg in packages]
  File "/usr/local/lib/python3.10/site-packages/celery/loaders/base.py", line 246, in <listcomp>
    return [find_related_module(pkg, related_name) for pkg in packages]
  File "/usr/local/lib/python3.10/site-packages/celery/loaders/base.py", line 278, in find_related_module
    raise e
  File "/usr/local/lib/python3.10/site-packages/celery/loaders/base.py", line 270, in find_related_module
    return importlib.import_module(module_name)
  File "/usr/local/lib/python3.10/importlib/__init__.py", line 126, in import_module
    return _bootstrap._gcd_import(name[level:], package, level)
  File "<frozen importlib._bootstrap>", line 1050, in _gcd_import
  File "<frozen importlib._bootstrap>", line 1027, in _find_and_load
  File "<frozen importlib._bootstrap>", line 1006, in _find_and_load_unlocked
  File "<frozen importlib._bootstrap>", line 688, in _load_unlocked
  File "<frozen importlib._bootstrap_external>", line 883, in exec_module
  File "<frozen importlib._bootstrap>", line 241, in _call_with_frames_removed
  File "/app/core/tasks.py", line 5, in <module>
    from .ml.models.chronic_disease_model import ChronicDiseaseModel
ModuleNotFoundError: No module named 'core.ml.models.chronic_disease_model'
Watching for file changes with StatReloader
Signal handler <promise@0xffff7f350180 --> <bound method Celery._autodiscover_tasks of <Celery enterprise_data_system at 0xffff7f2dccd0>>> raised: ModuleNotFoundError("No module named 'torch'")
Traceback (most recent call last):
  File "/usr/local/lib/python3.10/site-packages/celery/utils/dispatch/signal.py", line 276, in send
    response = receiver(signal=self, sender=sender, **named)
  File "/usr/local/lib/python3.10/site-packages/vine/promises.py", line 161, in __call__
    return self.throw()
  File "/usr/local/lib/python3.10/site-packages/vine/promises.py", line 158, in __call__
    retval = fun(*final_args, **final_kwargs)
  File "/usr/local/lib/python3.10/site-packages/celery/app/base.py", line 694, in _autodiscover_tasks
    return self._autodiscover_tasks_from_fixups(related_name)
  File "/usr/local/lib/python3.10/site-packages/celery/app/base.py", line 703, in _autodiscover_tasks_from_fixups
    return self._autodiscover_tasks_from_names([
  File "/usr/local/lib/python3.10/site-packages/celery/app/base.py", line 698, in _autodiscover_tasks_from_names
    return self.loader.autodiscover_tasks(
  File "/usr/local/lib/python3.10/site-packages/celery/loaders/base.py", line 220, in autodiscover_tasks
    mod.__name__ for mod in autodiscover_tasks(packages or (),
  File "/usr/local/lib/python3.10/site-packages/celery/loaders/base.py", line 246, in autodiscover_tasks
    return [find_related_module(pkg, related_name) for pkg in packages]
  File "/usr/local/lib/python3.10/site-packages/celery/loaders/base.py", line 246, in <listcomp>
    return [find_related_module(pkg, related_name) for pkg in packages]
  File "/usr/local/lib/python3.10/site-packages/celery/loaders/base.py", line 278, in find_related_module
    raise e
  File "/usr/local/lib/python3.10/site-packages/celery/loaders/base.py", line 270, in find_related_module
    return importlib.import_module(module_name)
  File "/usr/local/lib/python3.10/importlib/__init__.py", line 126, in import_module
    return _bootstrap._gcd_import(name[level:], package, level)
  File "<frozen importlib._bootstrap>", line 1050, in _gcd_import
  File "<frozen importlib._bootstrap>", line 1027, in _find_and_load
  File "<frozen importlib._bootstrap>", line 1006, in _find_and_load_unlocked
  File "<frozen importlib._bootstrap>", line 688, in _load_unlocked
  File "<frozen importlib._bootstrap_external>", line 883, in exec_module
  File "<frozen importlib._bootstrap>", line 241, in _call_with_frames_removed
  File "/app/core/tasks.py", line 5, in <module>
    from .ml.models.chronic_disease_model import ChronicDiseaseModel
  File "/app/core/ml/models/chronic_disease_model.py", line 4, in <module>
    from .base_model import BaseModel
  File "/app/core/ml/models/base_model.py", line 8, in <module>
    import torch
ModuleNotFoundError: No module named 'torch'
Watching for file changes with StatReloader
Signal handler <promise@0xffffa8164180 --> <bound method Celery._autodiscover_tasks of <Celery enterprise_data_system at 0xffffa80ecee0>>> raised: ImportError("cannot import name 'ChronicDiseaseModel' from 'core.ml.models.chronic_disease_model' (/app/core/ml/models/chronic_disease_model.py)")
Traceback (most recent call last):
  File "/usr/local/lib/python3.10/site-packages/celery/utils/dispatch/signal.py", line 276, in send
    response = receiver(signal=self, sender=sender, **named)
  File "/usr/local/lib/python3.10/site-packages/vine/promises.py", line 161, in __call__
    return self.throw()
  File "/usr/local/lib/python3.10/site-packages/vine/promises.py", line 158, in __call__
    retval = fun(*final_args, **final_kwargs)
  File "/usr/local/lib/python3.10/site-packages/celery/app/base.py", line 694, in _autodiscover_tasks
    return self._autodiscover_tasks_from_fixups(related_name)
  File "/usr/local/lib/python3.10/site-packages/celery/app/base.py", line 703, in _autodiscover_tasks_from_fixups
    return self._autodiscover_tasks_from_names([
  File "/usr/local/lib/python3.10/site-packages/celery/app/base.py", line 698, in _autodiscover_tasks_from_names
    return self.loader.autodiscover_tasks(
  File "/usr/local/lib/python3.10/site-packages/celery/loaders/base.py", line 220, in autodiscover_tasks
    mod.__name__ for mod in autodiscover_tasks(packages or (),
  File "/usr/local/lib/python3.10/site-packages/celery/loaders/base.py", line 246, in autodiscover_tasks
    return [find_related_module(pkg, related_name) for pkg in packages]
  File "/usr/local/lib/python3.10/site-packages/celery/loaders/base.py", line 246, in <listcomp>
    return [find_related_module(pkg, related_name) for pkg in packages]
  File "/usr/local/lib/python3.10/site-packages/celery/loaders/base.py", line 270, in find_related_module
    return importlib.import_module(module_name)
  File "/usr/local/lib/python3.10/importlib/__init__.py", line 126, in import_module
    return _bootstrap._gcd_import(name[level:], package, level)
  File "<frozen importlib._bootstrap>", line 1050, in _gcd_import
  File "<frozen importlib._bootstrap>", line 1027, in _find_and_load
  File "<frozen importlib._bootstrap>", line 1006, in _find_and_load_unlocked
  File "<frozen importlib._bootstrap>", line 688, in _load_unlocked
  File "<frozen importlib._bootstrap_external>", line 883, in exec_module
  File "<frozen importlib._bootstrap>", line 241, in _call_with_frames_removed
  File "/app/core/tasks.py", line 5, in <module>
    from .ml.models.chronic_disease_model import ChronicDiseaseModel
ImportError: cannot import name 'ChronicDiseaseModel' from 'core.ml.models.chronic_disease_model' (/app/core/ml/models/chronic_disease_model.py)
Watching for file changes with StatReloader
Signal handler <promise@0xffff8806c180 --> <bound method Celery._autodiscover_tasks of <Celery enterprise_data_system at 0xffff87ff4ee0>>> raised: ImportError("cannot import name 'ChronicDiseaseModel' from 'core.ml.models.chronic_disease_model' (/app/core/ml/models/chronic_disease_model.py)")
Traceback (most recent call last):
  File "/usr/local/lib/python3.10/site-packages/celery/utils/dispatch/signal.py", line 276, in send
    response = receiver(signal=self, sender=sender, **named)
  File "/usr/local/lib/python3.10/site-packages/vine/promises.py", line 161, in __call__
    return self.throw()
  File "/usr/local/lib/python3.10/site-packages/vine/promises.py", line 158, in __call__
    retval = fun(*final_args, **final_kwargs)
  File "/usr/local/lib/python3.10/site-packages/celery/app/base.py", line 694, in _autodiscover_tasks
    return self._autodiscover_tasks_from_fixups(related_name)
  File "/usr/local/lib/python3.10/site-packages/celery/app/base.py", line 703, in _autodiscover_tasks_from_fixups
    return self._autodiscover_tasks_from_names([
  File "/usr/local/lib/python3.10/site-packages/celery/app/base.py", line 698, in _autodiscover_tasks_from_names
    return self.loader.autodiscover_tasks(
  File "/usr/local/lib/python3.10/site-packages/celery/loaders/base.py", line 220, in autodiscover_tasks
    mod.__name__ for mod in autodiscover_tasks(packages or (),
  File "/usr/local/lib/python3.10/site-packages/celery/loaders/base.py", line 246, in autodiscover_tasks
    return [find_related_module(pkg, related_name) for pkg in packages]
  File "/usr/local/lib/python3.10/site-packages/celery/loaders/base.py", line 246, in <listcomp>
    return [find_related_module(pkg, related_name) for pkg in packages]
  File "/usr/local/lib/python3.10/site-packages/celery/loaders/base.py", line 270, in find_related_module
    return importlib.import_module(module_name)
  File "/usr/local/lib/python3.10/importlib/__init__.py", line 126, in import_module
    return _bootstrap._gcd_import(name[level:], package, level)
  File "<frozen importlib._bootstrap>", line 1050, in _gcd_import
  File "<frozen importlib._bootstrap>", line 1027, in _find_and_load
  File "<frozen importlib._bootstrap>", line 1006, in _find_and_load_unlocked
  File "<frozen importlib._bootstrap>", line 688, in _load_unlocked
  File "<frozen importlib._bootstrap_external>", line 883, in exec_module
  File "<frozen importlib._bootstrap>", line 241, in _call_with_frames_removed
  File "/app/core/tasks.py", line 5, in <module>
    from .ml.models.chronic_disease_model import ChronicDiseaseModel
ImportError: cannot import name 'ChronicDiseaseModel' from 'core.ml.models.chronic_disease_model' (/app/core/ml/models/chronic_disease_model.py)
Signal handler <promise@0xffff81af4b80 --> <bound method Celery._autodiscover_tasks of <Celery enterprise_data_system at 0xffff81abd120>>> raised: ImportError("cannot import name 'ChronicDiseaseModel' from 'core.ml.models.chronic_disease_model' (/app/core/ml/models/chronic_disease_model.py)")
Traceback (most recent call last):
  File "/usr/local/lib/python3.10/site-packages/celery/utils/dispatch/signal.py", line 276, in send
    response = receiver(signal=self, sender=sender, **named)
  File "/usr/local/lib/python3.10/site-packages/vine/promises.py", line 161, in __call__
    return self.throw()
  File "/usr/local/lib/python3.10/site-packages/vine/promises.py", line 158, in __call__
    retval = fun(*final_args, **final_kwargs)
  File "/usr/local/lib/python3.10/site-packages/celery/app/base.py", line 694, in _autodiscover_tasks
    return self._autodiscover_tasks_from_fixups(related_name)
  File "/usr/local/lib/python3.10/site-packages/celery/app/base.py", line 703, in _autodiscover_tasks_from_fixups
    return self._autodiscover_tasks_from_names([
  File "/usr/local/lib/python3.10/site-packages/celery/app/base.py", line 698, in _autodiscover_tasks_from_names
    return self.loader.autodiscover_tasks(
  File "/usr/local/lib/python3.10/site-packages/celery/loaders/base.py", line 220, in autodiscover_tasks
    mod.__name__ for mod in autodiscover_tasks(packages or (),
  File "/usr/local/lib/python3.10/site-packages/celery/loaders/base.py", line 246, in autodiscover_tasks
    return [find_related_module(pkg, related_name) for pkg in packages]
  File "/usr/local/lib/python3.10/site-packages/celery/loaders/base.py", line 246, in <listcomp>
    return [find_related_module(pkg, related_name) for pkg in packages]
  File "/usr/local/lib/python3.10/site-packages/celery/loaders/base.py", line 270, in find_related_module
    return importlib.import_module(module_name)
  File "/usr/local/lib/python3.10/importlib/__init__.py", line 126, in import_module
    return _bootstrap._gcd_import(name[level:], package, level)
  File "<frozen importlib._bootstrap>", line 1050, in _gcd_import
  File "<frozen importlib._bootstrap>", line 1027, in _find_and_load
  File "<frozen importlib._bootstrap>", line 1006, in _find_and_load_unlocked
  File "<frozen importlib._bootstrap>", line 688, in _load_unlocked
  File "<frozen importlib._bootstrap_external>", line 883, in exec_module
  File "<frozen importlib._bootstrap>", line 241, in _call_with_frames_removed
  File "/app/core/tasks.py", line 5, in <module>
    from .ml.models.chronic_disease_model import ChronicDiseaseModel
ImportError: cannot import name 'ChronicDiseaseModel' from 'core.ml.models.chronic_disease_model' (/app/core/ml/models/chronic_disease_model.py)
Signal handler <promise@0xffff83b6cb80 --> <bound method Celery._autodiscover_tasks of <Celery enterprise_data_system at 0xffff83b35120>>> raised: ImportError("cannot import name 'ChurnPredictionModel' from 'core.ml.models.churn_prediction_model' (/app/core/ml/models/churn_prediction_model.py)")
Traceback (most recent call last):
  File "/usr/local/lib/python3.10/site-packages/celery/utils/dispatch/signal.py", line 276, in send
    response = receiver(signal=self, sender=sender, **named)
  File "/usr/local/lib/python3.10/site-packages/vine/promises.py", line 161, in __call__
    return self.throw()
  File "/usr/local/lib/python3.10/site-packages/vine/promises.py", line 158, in __call__
    retval = fun(*final_args, **final_kwargs)
  File "/usr/local/lib/python3.10/site-packages/celery/app/base.py", line 694, in _autodiscover_tasks
    return self._autodiscover_tasks_from_fixups(related_name)
  File "/usr/local/lib/python3.10/site-packages/celery/app/base.py", line 703, in _autodiscover_tasks_from_fixups
    return self._autodiscover_tasks_from_names([
  File "/usr/local/lib/python3.10/site-packages/celery/app/base.py", line 698, in _autodiscover_tasks_from_names
    return self.loader.autodiscover_tasks(
  File "/usr/local/lib/python3.10/site-packages/celery/loaders/base.py", line 220, in autodiscover_tasks
    mod.__name__ for mod in autodiscover_tasks(packages or (),
  File "/usr/local/lib/python3.10/site-packages/celery/loaders/base.py", line 246, in autodiscover_tasks
    return [find_related_module(pkg, related_name) for pkg in packages]
  File "/usr/local/lib/python3.10/site-packages/celery/loaders/base.py", line 246, in <listcomp>
    return [find_related_module(pkg, related_name) for pkg in packages]
  File "/usr/local/lib/python3.10/site-packages/celery/loaders/base.py", line 270, in find_related_module
    return importlib.import_module(module_name)
  File "/usr/local/lib/python3.10/importlib/__init__.py", line 126, in import_module
    return _bootstrap._gcd_import(name[level:], package, level)
  File "<frozen importlib._bootstrap>", line 1050, in _gcd_import
  File "<frozen importlib._bootstrap>", line 1027, in _find_and_load
  File "<frozen importlib._bootstrap>", line 1006, in _find_and_load_unlocked
  File "<frozen importlib._bootstrap>", line 688, in _load_unlocked
  File "<frozen importlib._bootstrap_external>", line 883, in exec_module
  File "<frozen importlib._bootstrap>", line 241, in _call_with_frames_removed
  File "/app/core/tasks.py", line 6, in <module>
    from .ml.models.churn_prediction_model import ChurnPredictionModel
ImportError: cannot import name 'ChurnPredictionModel' from 'core.ml.models.churn_prediction_model' (/app/core/ml/models/churn_prediction_model.py)
Watching for file changes with StatReloader
Watching for file changes with StatReloader
Watching for file changes with StatReloader
Watching for file changes with StatReloader
Watching for file changes with StatReloader
Watching for file changes with StatReloader
Watching for file changes with StatReloader
Watching for file changes with StatReloader
Watching for file changes with StatReloader
Watching for file changes with StatReloader
Watching for file changes with StatReloader
Not Found: /
"GET / HTTP/1.1" 404 2288
Not Found: /favicon.ico
"GET /favicon.ico HTTP/1.1" 404 2339
Watching for file changes with StatReloader
Watching for file changes with StatReloader
Forbidden: /api/customers/
Forbidden: /api/contracts/analytics/
"GET /api/customers/ HTTP/1.1" 403 58
"GET /api/contracts/analytics/ HTTP/1.1" 403 58
Watching for file changes with StatReloader
Forbidden: /api/contracts/analytics/
Forbidden: /api/customers/
"GET /api/contracts/analytics/ HTTP/1.1" 403 58
"GET /api/customers/ HTTP/1.1" 403 58
Watching for file changes with StatReloader
Forbidden: /api/contracts/analytics/
Forbidden: /api/customers/
"GET /api/contracts/analytics/ HTTP/1.1" 403 58
"GET /api/customers/ HTTP/1.1" 403 58
Watching for file changes with StatReloader
Forbidden: /api/customers/
Forbidden: /api/contracts/analytics/
"GET /api/customers/ HTTP/1.1" 403 58
"GET /api/contracts/analytics/ HTTP/1.1" 403 58
Watching for file changes with StatReloader
Forbidden: /api/contracts/analytics/
Forbidden: /api/customers/
"GET /api/contracts/analytics/ HTTP/1.1" 403 58
"GET /api/customers/ HTTP/1.1" 403 58
Watching for file changes with StatReloader
Forbidden: /api/customers/
Forbidden: /api/contracts/analytics/
"GET /api/customers/ HTTP/1.1" 403 58
"GET /api/contracts/analytics/ HTTP/1.1" 403 58
Watching for file changes with StatReloader
Forbidden: /api/customers/
Forbidden: /api/contracts/analytics/
"GET /api/customers/ HTTP/1.1" 403 58
"GET /api/contracts/analytics/ HTTP/1.1" 403 58
Forbidden: /api/contracts/
"GET /api/contracts/ HTTP/1.1" 403 58
Forbidden: /api/customers/
"GET /api/customers/ HTTP/1.1" 403 58
Forbidden: /api/customers/
Forbidden: /api/contracts/analytics/
"GET /api/contracts/analytics/ HTTP/1.1" 403 58
"GET /api/customers/ HTTP/1.1" 403 58
Forbidden: /api/customers/
Forbidden: /api/contracts/analytics/
"GET /api/customers/ HTTP/1.1" 403 58
"GET /api/contracts/analytics/ HTTP/1.1" 403 58
Watching for file changes with StatReloader
Watching for file changes with StatReloader
Forbidden: /api/customers/
Forbidden: /api/contracts/analytics/
"GET /api/customers/ HTTP/1.1" 403 58
"GET /api/contracts/analytics/ HTTP/1.1" 403 58
Watching for file changes with StatReloader
Forbidden: /api/contracts/analytics/
Forbidden: /api/customers/
"GET /api/contracts/analytics/ HTTP/1.1" 403 58
"GET /api/customers/ HTTP/1.1" 403 58
Watching for file changes with StatReloader
Forbidden: /api/customers/
Forbidden: /api/contracts/analytics/
"GET /api/customers/ HTTP/1.1" 403 58
"GET /api/contracts/analytics/ HTTP/1.1" 403 58
/app/enterprise_data_system/core/views.py changed, reloading.
Watching for file changes with StatReloader
Watching for file changes with StatReloader
"GET /api/customers/ HTTP/1.1" 200 405
Internal Server Error: /api/contracts/analytics/
Traceback (most recent call last):
  File "/usr/local/lib/python3.10/site-packages/django/core/handlers/exception.py", line 55, in inner
    response = get_response(request)
  File "/usr/local/lib/python3.10/site-packages/django/core/handlers/base.py", line 197, in _get_response
    response = wrapped_callback(request, *callback_args, **callback_kwargs)
  File "/usr/local/lib/python3.10/site-packages/django/views/decorators/csrf.py", line 65, in _view_wrapper
    return view_func(request, *args, **kwargs)
  File "/usr/local/lib/python3.10/site-packages/rest_framework/viewsets.py", line 125, in view
    return self.dispatch(request, *args, **kwargs)
  File "/usr/local/lib/python3.10/site-packages/rest_framework/views.py", line 509, in dispatch
    response = self.handle_exception(exc)
  File "/usr/local/lib/python3.10/site-packages/rest_framework/views.py", line 469, in handle_exception
    self.raise_uncaught_exception(exc)
  File "/usr/local/lib/python3.10/site-packages/rest_framework/views.py", line 480, in raise_uncaught_exception
    raise exc
  File "/usr/local/lib/python3.10/site-packages/rest_framework/views.py", line 506, in dispatch
    response = handler(request, *args, **kwargs)
  File "/app/enterprise_data_system/core/views.py", line 125, in analytics
    total_premium = Contract.objects.filter(status='active').aggregate(Sum('premium'))['premium__sum']
  File "/usr/local/lib/python3.10/site-packages/django/db/models/query.py", line 602, in aggregate
    return self.query.chain().get_aggregation(self.db, kwargs)
  File "/usr/local/lib/python3.10/site-packages/django/db/models/sql/query.py", line 446, in get_aggregation
    aggregate = aggregate_expr.resolve_expression(
  File "/usr/local/lib/python3.10/site-packages/django/db/models/aggregates.py", line 64, in resolve_expression
    c = super().resolve_expression(query, allow_joins, reuse, summarize)
  File "/usr/local/lib/python3.10/site-packages/django/db/models/expressions.py", line 975, in resolve_expression
    c.source_expressions[pos] = arg.resolve_expression(
  File "/usr/local/lib/python3.10/site-packages/django/db/models/expressions.py", line 854, in resolve_expression
    return query.resolve_ref(self.name, allow_joins, reuse, summarize)
  File "/usr/local/lib/python3.10/site-packages/django/db/models/sql/query.py", line 2001, in resolve_ref
    join_info = self.setup_joins(
  File "/usr/local/lib/python3.10/site-packages/django/db/models/sql/query.py", line 1854, in setup_joins
    path, final_field, targets, rest = self.names_to_path(
  File "/usr/local/lib/python3.10/site-packages/django/db/models/sql/query.py", line 1759, in names_to_path
    raise FieldError(
django.core.exceptions.FieldError: Cannot resolve keyword 'premium' into field. Choices are: account, account_id, business, business_id, contract_num, contractbankaccount, contractcreditcard, contractpayment, coverage, duration, id, in_force, language, plan, plan_id, series, series_id, status, status_date
"GET /api/contracts/analytics/ HTTP/1.1" 500 127543
Watching for file changes with StatReloader
/app/enterprise_data_system/core/views.py changed, reloading.
Watching for file changes with StatReloader
/app/enterprise_data_system/core/views.py changed, reloading.
Watching for file changes with StatReloader
/app/enterprise_data_system/core/views.py changed, reloading.
Watching for file changes with StatReloader
Watching for file changes with StatReloader
"GET /api/customers/ HTTP/1.1" 200 405
"GET /api/contracts/analytics/ HTTP/1.1" 200 142
Watching for file changes with StatReloader
"GET /api/customers/ HTTP/1.1" 200 405
"GET /api/contracts/analytics/ HTTP/1.1" 200 142
Watching for file changes with StatReloader
Watching for file changes with StatReloader
"GET /api/customers/ HTTP/1.1" 200 405
"GET /api/contracts/analytics/ HTTP/1.1" 200 142
Watching for file changes with StatReloader
"GET /api/customers/ HTTP/1.1" 200 405
"GET /api/contracts/analytics/ HTTP/1.1" 200 142
Watching for file changes with StatReloader
Watching for file changes with StatReloader
"GET /api/customers/ HTTP/1.1" 200 405
"GET /api/contracts/analytics/ HTTP/1.1" 200 142
Watching for file changes with StatReloader
"GET /api/customers/ HTTP/1.1" 200 405
"GET /api/contracts/analytics/ HTTP/1.1" 200 142
Watching for file changes with StatReloader
"GET /api/customers/ HTTP/1.1" 200 405
"GET /api/contracts/analytics/ HTTP/1.1" 200 142
"GET /api/customers/ HTTP/1.1" 200 405
"GET /api/contracts/analytics/ HTTP/1.1" 200 142
Watching for file changes with StatReloader
"GET /api/customers/ HTTP/1.1" 200 405
"GET /api/contracts/analytics/ HTTP/1.1" 200 142
Watching for file changes with StatReloader
"GET /api/customers/ HTTP/1.1" 200 405
"GET /api/contracts/analytics/ HTTP/1.1" 200 142
/app/enterprise_data_system/enterprise_data_system/settings.py changed, reloading.
Watching for file changes with StatReloader
Watching for file changes with StatReloader
"GET /api/customers/ HTTP/1.1" 200 405
"GET /api/contracts/analytics/ HTTP/1.1" 200 142
Watching for file changes with StatReloader
"GET /api/customers/ HTTP/1.1" 200 405
"GET /api/contracts/analytics/ HTTP/1.1" 200 142
Invalid HTTP_HOST header: 'backend:8000'. You may need to add 'backend' to ALLOWED_HOSTS.
Traceback (most recent call last):
  File "/usr/local/lib/python3.10/site-packages/django/core/handlers/exception.py", line 55, in inner
    response = get_response(request)
  File "/usr/local/lib/python3.10/site-packages/django/utils/deprecation.py", line 133, in __call__
    response = self.process_request(request)
  File "/usr/local/lib/python3.10/site-packages/django/middleware/common.py", line 48, in process_request
    host = request.get_host()
  File "/usr/local/lib/python3.10/site-packages/django/http/request.py", line 150, in get_host
    raise DisallowedHost(msg)
django.core.exceptions.DisallowedHost: Invalid HTTP_HOST header: 'backend:8000'. You may need to add 'backend' to ALLOWED_HOSTS.
Bad Request: /customers/
"GET /customers/ HTTP/1.1" 400 14151
/app/enterprise_data_system/enterprise_data_system/settings.py changed, reloading.
Watching for file changes with StatReloader
Watching for file changes with StatReloader
"GET /api/customers/ HTTP/1.1" 200 405
"GET /api/contracts/analytics/ HTTP/1.1" 200 142
/app/enterprise_data_system/enterprise_data_system/settings.py changed, reloading.
Watching for file changes with StatReloader
Watching for file changes with StatReloader
"GET /api/customers/ HTTP/1.1" 200 405
"GET /api/contracts/analytics/ HTTP/1.1" 200 142
"GET /api/customers/ HTTP/1.1" 200 405
"GET /api/contracts/analytics/ HTTP/1.1" 200 142
"GET /api/customers/ HTTP/1.1" 200 405
"GET /api/contracts/analytics/ HTTP/1.1" 200 142
Invalid HTTP_HOST header: 'backend:8000'. You may need to add 'backend' to ALLOWED_HOSTS.
Traceback (most recent call last):
  File "/usr/local/lib/python3.10/site-packages/django/core/handlers/exception.py", line 55, in inner
    response = get_response(request)
  File "/usr/local/lib/python3.10/site-packages/django/utils/deprecation.py", line 133, in __call__
    response = self.process_request(request)
  File "/usr/local/lib/python3.10/site-packages/django/middleware/common.py", line 48, in process_request
    host = request.get_host()
  File "/usr/local/lib/python3.10/site-packages/django/http/request.py", line 150, in get_host
    raise DisallowedHost(msg)
django.core.exceptions.DisallowedHost: Invalid HTTP_HOST header: 'backend:8000'. You may need to add 'backend' to ALLOWED_HOSTS.
Bad Request: /analytics/dashboard
"GET /analytics/dashboard HTTP/1.1" 400 62881
"GET /api/customers/ HTTP/1.1" 200 405
"GET /api/contracts/analytics/ HTTP/1.1" 200 142
"GET /api/contracts/ HTTP/1.1" 200 52
/app/enterprise_data_system/enterprise_data_system/settings.py changed, reloading.
Watching for file changes with StatReloader
Watching for file changes with StatReloader
Watching for file changes with StatReloader
"GET /api/customers/ HTTP/1.1" 200 405
"GET /api/contracts/analytics/ HTTP/1.1" 200 142
"GET /api/contracts/analytics/ HTTP/1.1" 200 142
/app/enterprise_data_system/enterprise_data_system/settings.py changed, reloading.
Watching for file changes with StatReloader
/app/enterprise_data_system/enterprise_data_system/settings.py changed, reloading.
Watching for file changes with StatReloader
"GET /api/customers/ HTTP/1.1" 200 405
/app/enterprise_data_system/enterprise_data_system/settings.py changed, reloading.
Watching for file changes with StatReloader
Watching for file changes with StatReloader
"GET /api/customers/ HTTP/1.1" 200 1845
"GET /api/contracts/analytics/ HTTP/1.1" 200 166
Not Found: /contracts/analytics/
Not Found: /customers/
"GET /contracts/analytics/ HTTP/1.1" 404 2364
"GET /customers/ HTTP/1.1" 404 2334
"GET /api/customers/ HTTP/1.1" 200 1843
"GET /api/contracts/analytics/ HTTP/1.1" 200 166
"GET /api/customers/ HTTP/1.1" 200 1843
"GET /api/contracts/analytics/ HTTP/1.1" 200 166
"GET /api/customers/ HTTP/1.1" 200 1843
"GET /api/contracts/ HTTP/1.1" 200 1937
"GET /api/customers/ HTTP/1.1" 200 1843
"GET /api/contracts/analytics/ HTTP/1.1" 200 166
"GET /api/customers/ HTTP/1.1" 200 1843
"GET /api/contracts/ HTTP/1.1" 200 1937
/app/enterprise_data_system/core/views.py changed, reloading.
Watching for file changes with StatReloader
/app/enterprise_data_system/core/views.py changed, reloading.
Watching for file changes with StatReloader
Watching for file changes with StatReloader
"GET /api/customers/ HTTP/1.1" 200 1843
"GET /api/contracts/analytics/ HTTP/1.1" 200 167
"GET /api/customers/ HTTP/1.1" 200 1843
"GET /api/contracts/analytics/ HTTP/1.1" 200 167
"GET /api/contracts/analytics/ HTTP/1.1" 200 167
"GET /api/contracts/ HTTP/1.1" 200 1937
"GET /api/customers/ HTTP/1.1" 200 1843
"GET /api/contracts/analytics/ HTTP/1.1" 200 173
"GET /api/customers/ HTTP/1.1" 200 1843
"GET /api/contracts/analytics/ HTTP/1.1" 200 173
"GET /api/customers/ HTTP/1.1" 200 1843
"GET /api/customers/ HTTP/1.1" 200 1843
"GET /api/contracts/analytics/ HTTP/1.1" 200 173
"GET /api/contracts/ HTTP/1.1" 200 1937
"GET /api/contracts/analytics/ HTTP/1.1" 200 173
"GET /api/contracts/ HTTP/1.1" 200 1937
"GET /api/contracts/ HTTP/1.1" 200 1937
"GET /api/customers/ HTTP/1.1" 200 1843
"GET /api/contracts/analytics/ HTTP/1.1" 200 221
"GET /api/customers/ HTTP/1.1" 200 1843
"GET /api/contracts/analytics/ HTTP/1.1" 200 221
"GET /api/contracts/ HTTP/1.1" 200 1967
"GET /api/contracts/analytics/ HTTP/1.1" 200 221
"GET /api/customers/ HTTP/1.1" 200 1843
"GET /api/contracts/analytics/ HTTP/1.1" 200 221
"GET /api/customers/ HTTP/1.1" 200 1843
"GET /api/customers/ HTTP/1.1" 200 1843
"GET /api/customers/ HTTP/1.1" 200 1843
"GET /api/customers/ HTTP/1.1" 200 1843
"GET /api/contracts/analytics/ HTTP/1.1" 200 221
"GET /api/customers/ HTTP/1.1" 200 1843
"GET /api/customers/ HTTP/1.1" 200 1843
"GET /api/customers/ HTTP/1.1" 200 1843
"GET /api/contracts/analytics/ HTTP/1.1" 200 221
Not Found: /api/quote/calculate
"POST /api/quote/calculate HTTP/1.1" 404 5735
"GET /api/customers/ HTTP/1.1" 200 1843
"GET /api/contracts/analytics/ HTTP/1.1" 200 221
"GET /api/customers/ HTTP/1.1" 200 1843
"GET /api/customers/ HTTP/1.1" 200 1843
"GET /api/contracts/analytics/ HTTP/1.1" 200 221
"GET /api/customers/ HTTP/1.1" 200 1843
"GET /api/contracts/analytics/ HTTP/1.1" 200 221
"GET /api/customers/ HTTP/1.1" 200 1843
"GET /api/contracts/analytics/ HTTP/1.1" 200 221
"GET /api/customers/ HTTP/1.1" 200 1843
"GET /api/contracts/analytics/ HTTP/1.1" 200 221
"GET /api/customers/ HTTP/1.1" 200 1843
"GET /api/contracts/analytics/ HTTP/1.1" 200 221
"GET /api/customers/ HTTP/1.1" 200 1843
"GET /api/contracts/analytics/ HTTP/1.1" 200 221
"GET /api/customers/ HTTP/1.1" 200 1843
"GET /api/contracts/analytics/ HTTP/1.1" 200 221
"GET /api/customers/ HTTP/1.1" 200 1843
"GET /api/contracts/analytics/ HTTP/1.1" 200 221
"GET /api/customers/ HTTP/1.1" 200 1843
"GET /api/contracts/analytics/ HTTP/1.1" 200 221
"GET /api/customers/ HTTP/1.1" 200 1843
"GET /api/contracts/analytics/ HTTP/1.1" 200 221
"GET /api/customers/ HTTP/1.1" 200 1843
"GET /api/contracts/analytics/ HTTP/1.1" 200 221
Not Found: /
"GET / HTTP/1.1" 404 2292
"GET /api/customers/ HTTP/1.1" 200 1843
"GET /api/contracts/analytics/ HTTP/1.1" 200 221
"GET /api/customers/ HTTP/1.1" 200 1843
"GET /api/contracts/analytics/ HTTP/1.1" 200 221
"GET /api/customers/ HTTP/1.1" 200 1843
"GET /api/contracts/analytics/ HTTP/1.1" 200 221
"GET /api/customers/ HTTP/1.1" 200 1843
"GET /api/contracts/analytics/ HTTP/1.1" 200 221
"GET /api/customers/ HTTP/1.1" 200 1843
"GET /api/contracts/analytics/ HTTP/1.1" 200 221
"GET /api/customers/ HTTP/1.1" 200 1843
Watching for file changes with StatReloader
"GET /api/customers/ HTTP/1.1" 200 1843
"GET /api/customers/ HTTP/1.1" 200 1843
"GET /api/contracts/analytics/ HTTP/1.1" 200 221
"GET /api/customers/ HTTP/1.1" 200 1843
"GET /api/customers/ HTTP/1.1" 200 1843
"GET /api/customers/ HTTP/1.1" 200 1843
"GET /api/contracts/analytics/ HTTP/1.1" 200 221
"GET /api/customers/ HTTP/1.1" 200 1843
"GET /api/contracts/ HTTP/1.1" 200 1967
"GET /api/contracts/ HTTP/1.1" 200 1967
"GET /api/customers/ HTTP/1.1" 200 1843
"GET /api/contracts/analytics/ HTTP/1.1" 200 221
"GET /api/customers/ HTTP/1.1" 200 1843
"GET /api/contracts/ HTTP/1.1" 200 1967
"GET /api/customers/ HTTP/1.1" 200 1843
"GET /api/customers/ HTTP/1.1" 200 1843
"GET /api/contracts/ HTTP/1.1" 200 1967
"GET /api/customers/ HTTP/1.1" 200 1843
"GET /api/contracts/analytics/ HTTP/1.1" 200 221
"GET /api/customers/ HTTP/1.1" 200 1843
"GET /api/customers/ HTTP/1.1" 200 1843
"GET /api/contracts/analytics/ HTTP/1.1" 200 221
"GET /api/contracts/ HTTP/1.1" 200 1967
"GET /api/customers/ HTTP/1.1" 200 1843
"GET /api/contracts/analytics/ HTTP/1.1" 200 221
"GET /api/contracts/ HTTP/1.1" 200 1965
"GET /api/contracts/ HTTP/1.1" 200 1965
"GET /api/customers/ HTTP/1.1" 200 1843
"GET /api/contracts/ HTTP/1.1" 200 1965
"GET /api/customers/ HTTP/1.1" 200 1843
"GET /api/contracts/ HTTP/1.1" 200 1965
"GET /api/contracts/analytics/ HTTP/1.1" 200 221
"GET /api/contracts/analytics/ HTTP/1.1" 200 221
"GET /api/contracts/analytics/ HTTP/1.1" 200 221
"GET /api/contracts/analytics/ HTTP/1.1" 200 221
"GET /api/contracts/analytics/ HTTP/1.1" 200 221
"GET /api/contracts/analytics/ HTTP/1.1" 200 221
"GET /api/contracts/analytics/ HTTP/1.1" 200 221
"GET /api/contracts/analytics/ HTTP/1.1" 200 221
"GET /api/customers/ HTTP/1.1" 200 1843
"GET /api/contracts/analytics/ HTTP/1.1" 200 221
"GET /api/customers/ HTTP/1.1" 200 1843
"GET /api/contracts/analytics/ HTTP/1.1" 200 221
"GET /api/customers/ HTTP/1.1" 200 1843
"GET /api/contracts/ HTTP/1.1" 200 1965
"GET /api/customers/ HTTP/1.1" 200 1843
Not Found: /api/customers/54/risk-analysis/
"GET /api/customers/54/risk-analysis/ HTTP/1.1" 404 5770
Not Found: /api/quotes/calculate/
"POST /api/quotes/calculate/ HTTP/1.1" 404 5741
Not Found: /api/quotes/calculate/
"POST /api/quotes/calculate/ HTTP/1.1" 404 5741
"GET /api/contracts/analytics/ HTTP/1.1" 200 221
"GET /api/customers/ HTTP/1.1" 200 1843
"GET /api/customers/ HTTP/1.1" 200 1843
"GET /api/contracts/analytics/ HTTP/1.1" 200 221
"GET /api/customers/ HTTP/1.1" 200 1843
"GET /api/customers/ HTTP/1.1" 200 1843
"GET /api/contracts/analytics/ HTTP/1.1" 200 221
"GET /api/customers/ HTTP/1.1" 200 1843
"GET /api/customers/ HTTP/1.1" 200 1843
"GET /api/customers/ HTTP/1.1" 200 1843
"GET /api/customers/ HTTP/1.1" 200 1843
"GET /api/customers/ HTTP/1.1" 200 1843
"GET /api/customers/ HTTP/1.1" 200 1843
"GET /api/customers/ HTTP/1.1" 200 1843
"GET /api/contracts/analytics/ HTTP/1.1" 200 221
"GET /api/customers/ HTTP/1.1" 200 1843
Not Found: /api/customers/56/risk-analysis/
"GET /api/customers/56/risk-analysis/ HTTP/1.1" 404 5770
"GET /api/contracts/ HTTP/1.1" 200 1965
"GET /api/customers/ HTTP/1.1" 200 1843
"GET /api/customers/ HTTP/1.1" 200 1843
"GET /api/customers/ HTTP/1.1" 200 1843
"GET /api/customers/ HTTP/1.1" 200 1843
Watching for file changes with StatReloader
"GET /api/customers/ HTTP/1.1" 200 1843
"GET /api/customers/ HTTP/1.1" 200 1843
"GET /api/contracts/analytics/ HTTP/1.1" 200 221
"GET /api/customers/ HTTP/1.1" 200 1843
"GET /api/contracts/ HTTP/1.1" 200 1965
"GET /api/customers/ HTTP/1.1" 200 1843
"GET /api/contracts/ HTTP/1.1" 200 1965
"GET /api/customers/ HTTP/1.1" 200 1843
"GET /api/customers/ HTTP/1.1" 200 1843
"GET /api/contracts/analytics/ HTTP/1.1" 200 221
"GET /api/customers/ HTTP/1.1" 200 1843
"GET /api/customers/ HTTP/1.1" 200 1843
"GET /api/customers/53/ HTTP/1.1" 200 175
"PUT /api/customers/53/ HTTP/1.1" 200 175
"GET /api/customers/ HTTP/1.1" 200 1841
"GET /api/customers/ HTTP/1.1" 200 1841
"GET /api/customers/54/ HTTP/1.1" 200 172
"PUT /api/customers/54/ HTTP/1.1" 200 172
"GET /api/customers/ HTTP/1.1" 200 1842
"GET /api/customers/ HTTP/1.1" 200 1842
"GET /api/customers/ HTTP/1.1" 200 1842
"GET /api/customers/ HTTP/1.1" 200 1842
"GET /api/contracts/ HTTP/1.1" 200 1965
"GET /api/contracts/analytics/ HTTP/1.1" 200 221
"GET /api/customers/ HTTP/1.1" 200 1842
"GET /api/contracts/ HTTP/1.1" 200 1965
"GET /api/customers/ HTTP/1.1" 200 1842
"GET /api/customers/ HTTP/1.1" 200 1842
"GET /api/customers/ HTTP/1.1" 200 1842
"GET /api/customers/ HTTP/1.1" 200 1842
/app/enterprise_data_system/core/serializers.py changed, reloading.
Watching for file changes with StatReloader
"GET /api/customers/ HTTP/1.1" 200 1938
/app/enterprise_data_system/core/models/customer_models.py changed, reloading.
Watching for file changes with StatReloader
/app/enterprise_data_system/core/serializers.py changed, reloading.
Watching for file changes with StatReloader
Internal Server Error: /api/customers/
Traceback (most recent call last):
  File "/usr/local/lib/python3.10/site-packages/django/db/models/fields/related_descriptors.py", line 473, in __get__
    rel_obj = self.related.get_cached_value(instance)
  File "/usr/local/lib/python3.10/site-packages/django/db/models/fields/mixins.py", line 15, in get_cached_value
    return instance._state.fields_cache[cache_name]
KeyError: 'customeridentity'

During handling of the above exception, another exception occurred:

Traceback (most recent call last):
  File "/usr/local/lib/python3.10/site-packages/django/db/backends/utils.py", line 89, in _execute
    return self.cursor.execute(sql, params)
psycopg2.errors.UndefinedColumn: column customeridentity.phone does not exist
LINE 1: ...ntity"."withholding", "customeridentity"."email", "customeri...
                                                             ^


The above exception was the direct cause of the following exception:

Traceback (most recent call last):
  File "/usr/local/lib/python3.10/site-packages/django/core/handlers/exception.py", line 55, in inner
    response = get_response(request)
  File "/usr/local/lib/python3.10/site-packages/django/core/handlers/base.py", line 197, in _get_response
    response = wrapped_callback(request, *callback_args, **callback_kwargs)
  File "/usr/local/lib/python3.10/site-packages/django/views/decorators/csrf.py", line 56, in wrapper_view
    return view_func(*args, **kwargs)
  File "/usr/local/lib/python3.10/site-packages/rest_framework/viewsets.py", line 125, in view
    return self.dispatch(request, *args, **kwargs)
  File "/usr/local/lib/python3.10/site-packages/rest_framework/views.py", line 509, in dispatch
    response = self.handle_exception(exc)
  File "/usr/local/lib/python3.10/site-packages/rest_framework/views.py", line 469, in handle_exception
    self.raise_uncaught_exception(exc)
  File "/usr/local/lib/python3.10/site-packages/rest_framework/views.py", line 480, in raise_uncaught_exception
    raise exc
  File "/usr/local/lib/python3.10/site-packages/rest_framework/views.py", line 506, in dispatch
    response = handler(request, *args, **kwargs)
  File "/usr/local/lib/python3.10/site-packages/rest_framework/mixins.py", line 43, in list
    return self.get_paginated_response(serializer.data)
  File "/usr/local/lib/python3.10/site-packages/rest_framework/serializers.py", line 768, in data
    ret = super().data
  File "/usr/local/lib/python3.10/site-packages/rest_framework/serializers.py", line 253, in data
    self._data = self.to_representation(self.instance)
  File "/usr/local/lib/python3.10/site-packages/rest_framework/serializers.py", line 686, in to_representation
    return [
  File "/usr/local/lib/python3.10/site-packages/rest_framework/serializers.py", line 687, in <listcomp>
    self.child.to_representation(item) for item in iterable
  File "/usr/local/lib/python3.10/site-packages/rest_framework/serializers.py", line 522, in to_representation
    ret[field.field_name] = field.to_representation(attribute)
  File "/usr/local/lib/python3.10/site-packages/rest_framework/fields.py", line 1838, in to_representation
    return method(value)
  File "/app/enterprise_data_system/core/serializers.py", line 27, in get_email
    return obj.customeridentity.email if hasattr(obj, 'customeridentity') else None
  File "/usr/local/lib/python3.10/site-packages/django/db/models/fields/related_descriptors.py", line 481, in __get__
    rel_obj = self.get_queryset(instance=instance).get(**filter_args)
  File "/usr/local/lib/python3.10/site-packages/django/db/models/query.py", line 633, in get
    num = len(clone)
  File "/usr/local/lib/python3.10/site-packages/django/db/models/query.py", line 380, in __len__
    self._fetch_all()
  File "/usr/local/lib/python3.10/site-packages/django/db/models/query.py", line 1881, in _fetch_all
    self._result_cache = list(self._iterable_class(self))
  File "/usr/local/lib/python3.10/site-packages/django/db/models/query.py", line 91, in __iter__
    results = compiler.execute_sql(
  File "/usr/local/lib/python3.10/site-packages/django/db/models/sql/compiler.py", line 1562, in execute_sql
    cursor.execute(sql, params)
  File "/usr/local/lib/python3.10/site-packages/django/db/backends/utils.py", line 102, in execute
    return super().execute(sql, params)
  File "/usr/local/lib/python3.10/site-packages/django/db/backends/utils.py", line 67, in execute
    return self._execute_with_wrappers(
  File "/usr/local/lib/python3.10/site-packages/django/db/backends/utils.py", line 80, in _execute_with_wrappers
    return executor(sql, params, many, context)
  File "/usr/local/lib/python3.10/site-packages/django/db/backends/utils.py", line 84, in _execute
    with self.db.wrap_database_errors:
  File "/usr/local/lib/python3.10/site-packages/django/db/utils.py", line 91, in __exit__
    raise dj_exc_value.with_traceback(traceback) from exc_value
  File "/usr/local/lib/python3.10/site-packages/django/db/backends/utils.py", line 89, in _execute
    return self.cursor.execute(sql, params)
django.db.utils.ProgrammingError: column customeridentity.phone does not exist
LINE 1: ...ntity"."withholding", "customeridentity"."email", "customeri...
                                                             ^

"GET /api/customers/ HTTP/1.1" 500 19056
Internal Server Error: /api/customers/
Traceback (most recent call last):
  File "/usr/local/lib/python3.10/site-packages/django/db/models/fields/related_descriptors.py", line 473, in __get__
    rel_obj = self.related.get_cached_value(instance)
  File "/usr/local/lib/python3.10/site-packages/django/db/models/fields/mixins.py", line 15, in get_cached_value
    return instance._state.fields_cache[cache_name]
KeyError: 'customeridentity'

During handling of the above exception, another exception occurred:

Traceback (most recent call last):
  File "/usr/local/lib/python3.10/site-packages/django/db/backends/utils.py", line 89, in _execute
    return self.cursor.execute(sql, params)
psycopg2.errors.UndefinedColumn: column customeridentity.phone does not exist
LINE 1: ...ntity"."withholding", "customeridentity"."email", "customeri...
                                                             ^


The above exception was the direct cause of the following exception:

Traceback (most recent call last):
  File "/usr/local/lib/python3.10/site-packages/django/core/handlers/exception.py", line 55, in inner
    response = get_response(request)
  File "/usr/local/lib/python3.10/site-packages/django/core/handlers/base.py", line 197, in _get_response
    response = wrapped_callback(request, *callback_args, **callback_kwargs)
  File "/usr/local/lib/python3.10/site-packages/django/views/decorators/csrf.py", line 56, in wrapper_view
    return view_func(*args, **kwargs)
  File "/usr/local/lib/python3.10/site-packages/rest_framework/viewsets.py", line 125, in view
    return self.dispatch(request, *args, **kwargs)
  File "/usr/local/lib/python3.10/site-packages/rest_framework/views.py", line 509, in dispatch
    response = self.handle_exception(exc)
  File "/usr/local/lib/python3.10/site-packages/rest_framework/views.py", line 469, in handle_exception
    self.raise_uncaught_exception(exc)
  File "/usr/local/lib/python3.10/site-packages/rest_framework/views.py", line 480, in raise_uncaught_exception
    raise exc
  File "/usr/local/lib/python3.10/site-packages/rest_framework/views.py", line 506, in dispatch
    response = handler(request, *args, **kwargs)
  File "/usr/local/lib/python3.10/site-packages/rest_framework/mixins.py", line 43, in list
    return self.get_paginated_response(serializer.data)
  File "/usr/local/lib/python3.10/site-packages/rest_framework/serializers.py", line 768, in data
    ret = super().data
  File "/usr/local/lib/python3.10/site-packages/rest_framework/serializers.py", line 253, in data
    self._data = self.to_representation(self.instance)
  File "/usr/local/lib/python3.10/site-packages/rest_framework/serializers.py", line 686, in to_representation
    return [
  File "/usr/local/lib/python3.10/site-packages/rest_framework/serializers.py", line 687, in <listcomp>
    self.child.to_representation(item) for item in iterable
  File "/usr/local/lib/python3.10/site-packages/rest_framework/serializers.py", line 522, in to_representation
    ret[field.field_name] = field.to_representation(attribute)
  File "/usr/local/lib/python3.10/site-packages/rest_framework/fields.py", line 1838, in to_representation
    return method(value)
  File "/app/enterprise_data_system/core/serializers.py", line 27, in get_email
    return obj.customeridentity.email if hasattr(obj, 'customeridentity') else None
  File "/usr/local/lib/python3.10/site-packages/django/db/models/fields/related_descriptors.py", line 481, in __get__
    rel_obj = self.get_queryset(instance=instance).get(**filter_args)
  File "/usr/local/lib/python3.10/site-packages/django/db/models/query.py", line 633, in get
    num = len(clone)
  File "/usr/local/lib/python3.10/site-packages/django/db/models/query.py", line 380, in __len__
    self._fetch_all()
  File "/usr/local/lib/python3.10/site-packages/django/db/models/query.py", line 1881, in _fetch_all
    self._result_cache = list(self._iterable_class(self))
  File "/usr/local/lib/python3.10/site-packages/django/db/models/query.py", line 91, in __iter__
    results = compiler.execute_sql(
  File "/usr/local/lib/python3.10/site-packages/django/db/models/sql/compiler.py", line 1562, in execute_sql
    cursor.execute(sql, params)
  File "/usr/local/lib/python3.10/site-packages/django/db/backends/utils.py", line 102, in execute
    return super().execute(sql, params)
  File "/usr/local/lib/python3.10/site-packages/django/db/backends/utils.py", line 67, in execute
    return self._execute_with_wrappers(
  File "/usr/local/lib/python3.10/site-packages/django/db/backends/utils.py", line 80, in _execute_with_wrappers
    return executor(sql, params, many, context)
  File "/usr/local/lib/python3.10/site-packages/django/db/backends/utils.py", line 84, in _execute
    with self.db.wrap_database_errors:
  File "/usr/local/lib/python3.10/site-packages/django/db/utils.py", line 91, in __exit__
    raise dj_exc_value.with_traceback(traceback) from exc_value
  File "/usr/local/lib/python3.10/site-packages/django/db/backends/utils.py", line 89, in _execute
    return self.cursor.execute(sql, params)
django.db.utils.ProgrammingError: column customeridentity.phone does not exist
LINE 1: ...ntity"."withholding", "customeridentity"."email", "customeri...
                                                             ^

"GET /api/customers/ HTTP/1.1" 500 19056
Watching for file changes with StatReloader
/app/enterprise_data_system/core/models/customer_models.py changed, reloading.
Watching for file changes with StatReloader
"GET /api/customers/ HTTP/1.1" 200 2550
"GET /api/customers/ HTTP/1.1" 200 2550
"GET /api/customers/1/ HTTP/1.1" 200 246
"PUT /api/customers/1/ HTTP/1.1" 200 246
"GET /api/customers/ HTTP/1.1" 200 2542
/app/enterprise_data_system/core/models/customer_models.py changed, reloading.
Watching for file changes with StatReloader
/app/enterprise_data_system/core/serializers.py changed, reloading.
Watching for file changes with StatReloader
"GET /api/customers/ HTTP/1.1" 200 2660
"OPTIONS /auth/login/ HTTP/1.1" 200 0
Not Found: /auth/login/
"POST /auth/login/ HTTP/1.1" 404 2340
Not Found: /auth/login/
"POST /auth/login/ HTTP/1.1" 404 2340
Not Found: /auth/login/
"POST /auth/login/ HTTP/1.1" 404 2340
Not Found: /auth/login/
"POST /auth/login/ HTTP/1.1" 404 2340
Not Found: /auth/login/
"POST /auth/login/ HTTP/1.1" 404 2340
Not Found: /auth/login/
"POST /auth/login/ HTTP/1.1" 404 2340
Not Found: /auth/login/
"POST /auth/login/ HTTP/1.1" 404 2340
Watching for file changes with StatReloader
Not Found: /auth/login/
"POST /auth/login/ HTTP/1.1" 404 2340
Not Found: /auth/login/
"POST /auth/login/ HTTP/1.1" 404 2340
Not Found: /auth/login/
"POST /auth/login/ HTTP/1.1" 404 2340
/app/enterprise_data_system/core/views.py changed, reloading.
Watching for file changes with StatReloader
/app/enterprise_data_system/enterprise_data_system/settings.py changed, reloading.
Watching for file changes with StatReloader
Watching for file changes with StatReloader
"OPTIONS /auth/login/ HTTP/1.1" 200 0
Not Found: /auth/login/
"POST /auth/login/ HTTP/1.1" 404 2340
/app/enterprise_data_system/enterprise_data_system/urls.py changed, reloading.
Watching for file changes with StatReloader
Watching for file changes with StatReloader
"POST /auth/login/ HTTP/1.1" 200 517
"POST /auth/login/ HTTP/1.1" 200 517
"POST /auth/login/ HTTP/1.1" 200 517
Watching for file changes with StatReloader
Unauthorized: /auth/login/
"POST /auth/login/ HTTP/1.1" 401 36
"POST /auth/login/ HTTP/1.1" 200 517
"GET /api/customers/ HTTP/1.1" 200 2662
Watching for file changes with StatReloader
Watching for file changes with StatReloader
Watching for file changes with StatReloader
Watching for file changes with StatReloader
Watching for file changes with StatReloader
Watching for file changes with StatReloader
Watching for file changes with StatReloader
Watching for file changes with StatReloader
Watching for file changes with StatReloader
Watching for file changes with StatReloader
Watching for file changes with StatReloader
Watching for file changes with StatReloader
Watching for file changes with StatReloader
Watching for file changes with StatReloader
Watching for file changes with StatReloader
"OPTIONS /auth/login/ HTTP/1.1" 200 0
"POST /auth/login/ HTTP/1.1" 200 517
Watching for file changes with StatReloader
"OPTIONS /auth/login/ HTTP/1.1" 200 0
Unauthorized: /auth/login/
"POST /auth/login/ HTTP/1.1" 401 36
"OPTIONS /auth/login/ HTTP/1.1" 200 0
"POST /auth/login/ HTTP/1.1" 200 517
"OPTIONS /auth/login/ HTTP/1.1" 200 0
"POST /auth/login/ HTTP/1.1" 200 517
"OPTIONS /customers/ HTTP/1.1" 200 0
"OPTIONS /contracts/analytics/ HTTP/1.1" 200 0
Not Found: /contracts/analytics/
"GET /contracts/analytics/ HTTP/1.1" 404 2491
Not Found: /customers/
"GET /customers/ HTTP/1.1" 404 2461
"OPTIONS /auth/login/ HTTP/1.1" 200 0
"POST /auth/login/ HTTP/1.1" 200 517
"OPTIONS /customers/ HTTP/1.1" 200 0
"OPTIONS /contracts/analytics/ HTTP/1.1" 200 0
Not Found: /contracts/analytics/
"GET /contracts/analytics/ HTTP/1.1" 404 2491
Not Found: /customers/
"GET /customers/ HTTP/1.1" 404 2461
/app/enterprise_data_system/enterprise_data_system/urls.py changed, reloading.
Watching for file changes with StatReloader
"OPTIONS /auth/login/ HTTP/1.1" 200 0
"POST /auth/login/ HTTP/1.1" 200 517
"OPTIONS /customers/ HTTP/1.1" 200 0
"OPTIONS /contracts/analytics/ HTTP/1.1" 200 0
Not Found: /contracts/analytics/
"GET /contracts/analytics/ HTTP/1.1" 404 2491
Not Found: /customers/
"GET /customers/ HTTP/1.1" 404 2461
"OPTIONS /auth/login/ HTTP/1.1" 200 0
"POST /auth/login/ HTTP/1.1" 200 517
"OPTIONS /api/customers/ HTTP/1.1" 200 0
"OPTIONS /api/contracts/analytics/ HTTP/1.1" 200 0
"GET /api/contracts/analytics/ HTTP/1.1" 200 221
"GET /api/customers/ HTTP/1.1" 200 2663
"OPTIONS /auth/login/ HTTP/1.1" 200 0
"POST /auth/login/ HTTP/1.1" 200 517
"OPTIONS /api/customers/ HTTP/1.1" 200 0
"OPTIONS /api/contracts/analytics/ HTTP/1.1" 200 0
"GET /api/contracts/analytics/ HTTP/1.1" 200 221
"GET /api/customers/ HTTP/1.1" 200 2663
"OPTIONS /customers/ HTTP/1.1" 200 0
Not Found: /customers/
"GET /customers/ HTTP/1.1" 404 2461
"OPTIONS /auth/login/ HTTP/1.1" 200 0
"POST /auth/login/ HTTP/1.1" 200 517
"OPTIONS /api/customers/ HTTP/1.1" 200 0
"OPTIONS /api/contracts/analytics/ HTTP/1.1" 200 0
"GET /api/contracts/analytics/ HTTP/1.1" 200 221
"GET /api/customers/ HTTP/1.1" 200 2663
"GET /api/customers/ HTTP/1.1" 200 2663
"OPTIONS /api/contracts/ HTTP/1.1" 200 0
"GET /api/contracts/ HTTP/1.1" 200 1942
"GET /api/contracts/analytics/ HTTP/1.1" 200 221
"OPTIONS /auth/login/ HTTP/1.1" 200 0
"POST /auth/login/ HTTP/1.1" 200 517
"OPTIONS /api/customers/ HTTP/1.1" 200 0
"OPTIONS /api/contracts/analytics/ HTTP/1.1" 200 0
"GET /api/contracts/analytics/ HTTP/1.1" 200 221
"GET /api/customers/ HTTP/1.1" 200 2663
"GET /api/customers/ HTTP/1.1" 200 2663
"GET /api/customers/ HTTP/1.1" 200 2663
"OPTIONS /customers/1/ HTTP/1.1" 200 0
Not Found: /customers/1/
"GET /customers/1/ HTTP/1.1" 404 2467
"GET /api/customers/ HTTP/1.1" 200 2663
"OPTIONS /auth/login/ HTTP/1.1" 200 0
"POST /auth/login/ HTTP/1.1" 200 517
"OPTIONS /api/customers/ HTTP/1.1" 200 0
"OPTIONS /api/contracts/analytics/ HTTP/1.1" 200 0
"GET /api/contracts/analytics/ HTTP/1.1" 200 221
"GET /api/customers/ HTTP/1.1" 200 2663
"GET /api/customers/ HTTP/1.1" 200 2663
"OPTIONS /api/contracts/ HTTP/1.1" 200 0
"GET /api/contracts/ HTTP/1.1" 200 1942
/app/enterprise_data_system/core/serializers.py changed, reloading.
Watching for file changes with StatReloader
Watching for file changes with StatReloader
Watching for file changes with StatReloader
Watching for file changes with StatReloader
Watching for file changes with StatReloader
/app/enterprise_data_system/core/serializers.py changed, reloading.
Watching for file changes with StatReloader
Watching for file changes with StatReloader
"OPTIONS /auth/login/ HTTP/1.1" 200 0
"POST /auth/login/ HTTP/1.1" 200 517
"GET /api/contracts/ HTTP/1.1" 200 1540
"OPTIONS /api/contracts/analytics/ HTTP/1.1" 200 0
"GET /api/contracts/analytics/ HTTP/1.1" 200 221
/app/enterprise_data_system/core/serializers.py changed, reloading.
Watching for file changes with StatReloader
"OPTIONS /api/customers/ HTTP/1.1" 200 0
"GET /api/contracts/analytics/ HTTP/1.1" 200 221
"GET /api/customers/ HTTP/1.1" 200 2663
"GET /api/customers/ HTTP/1.1" 200 2663
"OPTIONS /api/customers/1/ HTTP/1.1" 200 0
"GET /api/customers/1/ HTTP/1.1" 200 251
Internal Server Error: /api/contracts/
Traceback (most recent call last):
  File "/usr/local/lib/python3.10/site-packages/django/core/handlers/exception.py", line 55, in inner
    response = get_response(request)
  File "/usr/local/lib/python3.10/site-packages/django/core/handlers/base.py", line 197, in _get_response
    response = wrapped_callback(request, *callback_args, **callback_kwargs)
  File "/usr/local/lib/python3.10/site-packages/django/views/decorators/csrf.py", line 56, in wrapper_view
    return view_func(*args, **kwargs)
  File "/usr/local/lib/python3.10/site-packages/rest_framework/viewsets.py", line 125, in view
    return self.dispatch(request, *args, **kwargs)
  File "/usr/local/lib/python3.10/site-packages/rest_framework/views.py", line 509, in dispatch
    response = self.handle_exception(exc)
  File "/usr/local/lib/python3.10/site-packages/rest_framework/views.py", line 469, in handle_exception
    self.raise_uncaught_exception(exc)
  File "/usr/local/lib/python3.10/site-packages/rest_framework/views.py", line 480, in raise_uncaught_exception
    raise exc
  File "/usr/local/lib/python3.10/site-packages/rest_framework/views.py", line 506, in dispatch
    response = handler(request, *args, **kwargs)
  File "/usr/local/lib/python3.10/site-packages/rest_framework/mixins.py", line 43, in list
    return self.get_paginated_response(serializer.data)
  File "/usr/local/lib/python3.10/site-packages/rest_framework/serializers.py", line 768, in data
    ret = super().data
  File "/usr/local/lib/python3.10/site-packages/rest_framework/serializers.py", line 253, in data
    self._data = self.to_representation(self.instance)
  File "/usr/local/lib/python3.10/site-packages/rest_framework/serializers.py", line 686, in to_representation
    return [
  File "/usr/local/lib/python3.10/site-packages/rest_framework/serializers.py", line 687, in <listcomp>
    self.child.to_representation(item) for item in iterable
  File "/usr/local/lib/python3.10/site-packages/rest_framework/serializers.py", line 522, in to_representation
    ret[field.field_name] = field.to_representation(attribute)
  File "/usr/local/lib/python3.10/site-packages/rest_framework/fields.py", line 1838, in to_representation
    return method(value)
  File "/app/enterprise_data_system/core/serializers.py", line 61, in get_customer_name
    return f"{obj.customer.first_name} {obj.customer.last_name}" if obj.customer else None
AttributeError: 'Contract' object has no attribute 'customer'
"GET /api/contracts/ HTTP/1.1" 500 127897
Internal Server Error: /api/contracts/
Traceback (most recent call last):
  File "/usr/local/lib/python3.10/site-packages/django/core/handlers/exception.py", line 55, in inner
    response = get_response(request)
  File "/usr/local/lib/python3.10/site-packages/django/core/handlers/base.py", line 197, in _get_response
    response = wrapped_callback(request, *callback_args, **callback_kwargs)
  File "/usr/local/lib/python3.10/site-packages/django/views/decorators/csrf.py", line 56, in wrapper_view
    return view_func(*args, **kwargs)
  File "/usr/local/lib/python3.10/site-packages/rest_framework/viewsets.py", line 125, in view
    return self.dispatch(request, *args, **kwargs)
  File "/usr/local/lib/python3.10/site-packages/rest_framework/views.py", line 509, in dispatch
    response = self.handle_exception(exc)
  File "/usr/local/lib/python3.10/site-packages/rest_framework/views.py", line 469, in handle_exception
    self.raise_uncaught_exception(exc)
  File "/usr/local/lib/python3.10/site-packages/rest_framework/views.py", line 480, in raise_uncaught_exception
    raise exc
  File "/usr/local/lib/python3.10/site-packages/rest_framework/views.py", line 506, in dispatch
    response = handler(request, *args, **kwargs)
  File "/usr/local/lib/python3.10/site-packages/rest_framework/mixins.py", line 43, in list
    return self.get_paginated_response(serializer.data)
  File "/usr/local/lib/python3.10/site-packages/rest_framework/serializers.py", line 768, in data
    ret = super().data
  File "/usr/local/lib/python3.10/site-packages/rest_framework/serializers.py", line 253, in data
    self._data = self.to_representation(self.instance)
  File "/usr/local/lib/python3.10/site-packages/rest_framework/serializers.py", line 686, in to_representation
    return [
  File "/usr/local/lib/python3.10/site-packages/rest_framework/serializers.py", line 687, in <listcomp>
    self.child.to_representation(item) for item in iterable
  File "/usr/local/lib/python3.10/site-packages/rest_framework/serializers.py", line 522, in to_representation
    ret[field.field_name] = field.to_representation(attribute)
  File "/usr/local/lib/python3.10/site-packages/rest_framework/fields.py", line 1838, in to_representation
    return method(value)
  File "/app/enterprise_data_system/core/serializers.py", line 61, in get_customer_name
    return f"{obj.customer.first_name} {obj.customer.last_name}" if obj.customer else None
AttributeError: 'Contract' object has no attribute 'customer'
"GET /api/contracts/ HTTP/1.1" 500 127897
"GET /api/customers/ HTTP/1.1" 200 2663
Internal Server Error: /api/contracts/
Traceback (most recent call last):
  File "/usr/local/lib/python3.10/site-packages/django/core/handlers/exception.py", line 55, in inner
    response = get_response(request)
  File "/usr/local/lib/python3.10/site-packages/django/core/handlers/base.py", line 197, in _get_response
    response = wrapped_callback(request, *callback_args, **callback_kwargs)
  File "/usr/local/lib/python3.10/site-packages/django/views/decorators/csrf.py", line 56, in wrapper_view
    return view_func(*args, **kwargs)
  File "/usr/local/lib/python3.10/site-packages/rest_framework/viewsets.py", line 125, in view
    return self.dispatch(request, *args, **kwargs)
  File "/usr/local/lib/python3.10/site-packages/rest_framework/views.py", line 509, in dispatch
    response = self.handle_exception(exc)
  File "/usr/local/lib/python3.10/site-packages/rest_framework/views.py", line 469, in handle_exception
    self.raise_uncaught_exception(exc)
  File "/usr/local/lib/python3.10/site-packages/rest_framework/views.py", line 480, in raise_uncaught_exception
    raise exc
  File "/usr/local/lib/python3.10/site-packages/rest_framework/views.py", line 506, in dispatch
    response = handler(request, *args, **kwargs)
  File "/usr/local/lib/python3.10/site-packages/rest_framework/mixins.py", line 43, in list
    return self.get_paginated_response(serializer.data)
  File "/usr/local/lib/python3.10/site-packages/rest_framework/serializers.py", line 768, in data
    ret = super().data
  File "/usr/local/lib/python3.10/site-packages/rest_framework/serializers.py", line 253, in data
    self._data = self.to_representation(self.instance)
  File "/usr/local/lib/python3.10/site-packages/rest_framework/serializers.py", line 686, in to_representation
    return [
  File "/usr/local/lib/python3.10/site-packages/rest_framework/serializers.py", line 687, in <listcomp>
    self.child.to_representation(item) for item in iterable
  File "/usr/local/lib/python3.10/site-packages/rest_framework/serializers.py", line 522, in to_representation
    ret[field.field_name] = field.to_representation(attribute)
  File "/usr/local/lib/python3.10/site-packages/rest_framework/fields.py", line 1838, in to_representation
    return method(value)
  File "/app/enterprise_data_system/core/serializers.py", line 61, in get_customer_name
    return f"{obj.customer.first_name} {obj.customer.last_name}" if obj.customer else None
AttributeError: 'Contract' object has no attribute 'customer'
"GET /api/contracts/ HTTP/1.1" 500 127897
Internal Server Error: /api/contracts/
Traceback (most recent call last):
  File "/usr/local/lib/python3.10/site-packages/django/core/handlers/exception.py", line 55, in inner
    response = get_response(request)
  File "/usr/local/lib/python3.10/site-packages/django/core/handlers/base.py", line 197, in _get_response
    response = wrapped_callback(request, *callback_args, **callback_kwargs)
  File "/usr/local/lib/python3.10/site-packages/django/views/decorators/csrf.py", line 56, in wrapper_view
    return view_func(*args, **kwargs)
  File "/usr/local/lib/python3.10/site-packages/rest_framework/viewsets.py", line 125, in view
    return self.dispatch(request, *args, **kwargs)
  File "/usr/local/lib/python3.10/site-packages/rest_framework/views.py", line 509, in dispatch
    response = self.handle_exception(exc)
  File "/usr/local/lib/python3.10/site-packages/rest_framework/views.py", line 469, in handle_exception
    self.raise_uncaught_exception(exc)
  File "/usr/local/lib/python3.10/site-packages/rest_framework/views.py", line 480, in raise_uncaught_exception
    raise exc
  File "/usr/local/lib/python3.10/site-packages/rest_framework/views.py", line 506, in dispatch
    response = handler(request, *args, **kwargs)
  File "/usr/local/lib/python3.10/site-packages/rest_framework/mixins.py", line 43, in list
    return self.get_paginated_response(serializer.data)
  File "/usr/local/lib/python3.10/site-packages/rest_framework/serializers.py", line 768, in data
    ret = super().data
  File "/usr/local/lib/python3.10/site-packages/rest_framework/serializers.py", line 253, in data
    self._data = self.to_representation(self.instance)
  File "/usr/local/lib/python3.10/site-packages/rest_framework/serializers.py", line 686, in to_representation
    return [
  File "/usr/local/lib/python3.10/site-packages/rest_framework/serializers.py", line 687, in <listcomp>
    self.child.to_representation(item) for item in iterable
  File "/usr/local/lib/python3.10/site-packages/rest_framework/serializers.py", line 522, in to_representation
    ret[field.field_name] = field.to_representation(attribute)
  File "/usr/local/lib/python3.10/site-packages/rest_framework/fields.py", line 1838, in to_representation
    return method(value)
  File "/app/enterprise_data_system/core/serializers.py", line 61, in get_customer_name
    return f"{obj.customer.first_name} {obj.customer.last_name}" if obj.customer else None
AttributeError: 'Contract' object has no attribute 'customer'
"GET /api/contracts/ HTTP/1.1" 500 127897
Internal Server Error: /api/contracts/
Traceback (most recent call last):
  File "/usr/local/lib/python3.10/site-packages/django/core/handlers/exception.py", line 55, in inner
    response = get_response(request)
  File "/usr/local/lib/python3.10/site-packages/django/core/handlers/base.py", line 197, in _get_response
    response = wrapped_callback(request, *callback_args, **callback_kwargs)
  File "/usr/local/lib/python3.10/site-packages/django/views/decorators/csrf.py", line 56, in wrapper_view
    return view_func(*args, **kwargs)
  File "/usr/local/lib/python3.10/site-packages/rest_framework/viewsets.py", line 125, in view
    return self.dispatch(request, *args, **kwargs)
  File "/usr/local/lib/python3.10/site-packages/rest_framework/views.py", line 509, in dispatch
    response = self.handle_exception(exc)
  File "/usr/local/lib/python3.10/site-packages/rest_framework/views.py", line 469, in handle_exception
    self.raise_uncaught_exception(exc)
  File "/usr/local/lib/python3.10/site-packages/rest_framework/views.py", line 480, in raise_uncaught_exception
    raise exc
  File "/usr/local/lib/python3.10/site-packages/rest_framework/views.py", line 506, in dispatch
    response = handler(request, *args, **kwargs)
  File "/usr/local/lib/python3.10/site-packages/rest_framework/mixins.py", line 43, in list
    return self.get_paginated_response(serializer.data)
  File "/usr/local/lib/python3.10/site-packages/rest_framework/serializers.py", line 768, in data
    ret = super().data
  File "/usr/local/lib/python3.10/site-packages/rest_framework/serializers.py", line 253, in data
    self._data = self.to_representation(self.instance)
  File "/usr/local/lib/python3.10/site-packages/rest_framework/serializers.py", line 686, in to_representation
    return [
  File "/usr/local/lib/python3.10/site-packages/rest_framework/serializers.py", line 687, in <listcomp>
    self.child.to_representation(item) for item in iterable
  File "/usr/local/lib/python3.10/site-packages/rest_framework/serializers.py", line 522, in to_representation
    ret[field.field_name] = field.to_representation(attribute)
  File "/usr/local/lib/python3.10/site-packages/rest_framework/fields.py", line 1838, in to_representation
    return method(value)
  File "/app/enterprise_data_system/core/serializers.py", line 61, in get_customer_name
    return f"{obj.customer.first_name} {obj.customer.last_name}" if obj.customer else None
AttributeError: 'Contract' object has no attribute 'customer'
"GET /api/contracts/ HTTP/1.1" 500 127897
Internal Server Error: /api/contracts/
Traceback (most recent call last):
  File "/usr/local/lib/python3.10/site-packages/django/core/handlers/exception.py", line 55, in inner
    response = get_response(request)
  File "/usr/local/lib/python3.10/site-packages/django/core/handlers/base.py", line 197, in _get_response
    response = wrapped_callback(request, *callback_args, **callback_kwargs)
  File "/usr/local/lib/python3.10/site-packages/django/views/decorators/csrf.py", line 56, in wrapper_view
    return view_func(*args, **kwargs)
  File "/usr/local/lib/python3.10/site-packages/rest_framework/viewsets.py", line 125, in view
    return self.dispatch(request, *args, **kwargs)
  File "/usr/local/lib/python3.10/site-packages/rest_framework/views.py", line 509, in dispatch
    response = self.handle_exception(exc)
  File "/usr/local/lib/python3.10/site-packages/rest_framework/views.py", line 469, in handle_exception
    self.raise_uncaught_exception(exc)
  File "/usr/local/lib/python3.10/site-packages/rest_framework/views.py", line 480, in raise_uncaught_exception
    raise exc
  File "/usr/local/lib/python3.10/site-packages/rest_framework/views.py", line 506, in dispatch
    response = handler(request, *args, **kwargs)
  File "/usr/local/lib/python3.10/site-packages/rest_framework/mixins.py", line 43, in list
    return self.get_paginated_response(serializer.data)
  File "/usr/local/lib/python3.10/site-packages/rest_framework/serializers.py", line 768, in data
    ret = super().data
  File "/usr/local/lib/python3.10/site-packages/rest_framework/serializers.py", line 253, in data
    self._data = self.to_representation(self.instance)
  File "/usr/local/lib/python3.10/site-packages/rest_framework/serializers.py", line 686, in to_representation
    return [
  File "/usr/local/lib/python3.10/site-packages/rest_framework/serializers.py", line 687, in <listcomp>
    self.child.to_representation(item) for item in iterable
  File "/usr/local/lib/python3.10/site-packages/rest_framework/serializers.py", line 522, in to_representation
    ret[field.field_name] = field.to_representation(attribute)
  File "/usr/local/lib/python3.10/site-packages/rest_framework/fields.py", line 1838, in to_representation
    return method(value)
  File "/app/enterprise_data_system/core/serializers.py", line 61, in get_customer_name
    return f"{obj.customer.first_name} {obj.customer.last_name}" if obj.customer else None
AttributeError: 'Contract' object has no attribute 'customer'
"GET /api/contracts/ HTTP/1.1" 500 127897
Internal Server Error: /api/contracts/
Traceback (most recent call last):
  File "/usr/local/lib/python3.10/site-packages/django/core/handlers/exception.py", line 55, in inner
    response = get_response(request)
  File "/usr/local/lib/python3.10/site-packages/django/core/handlers/base.py", line 197, in _get_response
    response = wrapped_callback(request, *callback_args, **callback_kwargs)
  File "/usr/local/lib/python3.10/site-packages/django/views/decorators/csrf.py", line 56, in wrapper_view
    return view_func(*args, **kwargs)
  File "/usr/local/lib/python3.10/site-packages/rest_framework/viewsets.py", line 125, in view
    return self.dispatch(request, *args, **kwargs)
  File "/usr/local/lib/python3.10/site-packages/rest_framework/views.py", line 509, in dispatch
    response = self.handle_exception(exc)
  File "/usr/local/lib/python3.10/site-packages/rest_framework/views.py", line 469, in handle_exception
    self.raise_uncaught_exception(exc)
  File "/usr/local/lib/python3.10/site-packages/rest_framework/views.py", line 480, in raise_uncaught_exception
    raise exc
  File "/usr/local/lib/python3.10/site-packages/rest_framework/views.py", line 506, in dispatch
    response = handler(request, *args, **kwargs)
  File "/usr/local/lib/python3.10/site-packages/rest_framework/mixins.py", line 43, in list
    return self.get_paginated_response(serializer.data)
  File "/usr/local/lib/python3.10/site-packages/rest_framework/serializers.py", line 768, in data
    ret = super().data
  File "/usr/local/lib/python3.10/site-packages/rest_framework/serializers.py", line 253, in data
    self._data = self.to_representation(self.instance)
  File "/usr/local/lib/python3.10/site-packages/rest_framework/serializers.py", line 686, in to_representation
    return [
  File "/usr/local/lib/python3.10/site-packages/rest_framework/serializers.py", line 687, in <listcomp>
    self.child.to_representation(item) for item in iterable
  File "/usr/local/lib/python3.10/site-packages/rest_framework/serializers.py", line 522, in to_representation
    ret[field.field_name] = field.to_representation(attribute)
  File "/usr/local/lib/python3.10/site-packages/rest_framework/fields.py", line 1838, in to_representation
    return method(value)
  File "/app/enterprise_data_system/core/serializers.py", line 61, in get_customer_name
    return f"{obj.customer.first_name} {obj.customer.last_name}" if obj.customer else None
AttributeError: 'Contract' object has no attribute 'customer'
"GET /api/contracts/ HTTP/1.1" 500 127897
Internal Server Error: /api/contracts/
Traceback (most recent call last):
  File "/usr/local/lib/python3.10/site-packages/django/core/handlers/exception.py", line 55, in inner
    response = get_response(request)
  File "/usr/local/lib/python3.10/site-packages/django/core/handlers/base.py", line 197, in _get_response
    response = wrapped_callback(request, *callback_args, **callback_kwargs)
  File "/usr/local/lib/python3.10/site-packages/django/views/decorators/csrf.py", line 56, in wrapper_view
    return view_func(*args, **kwargs)
  File "/usr/local/lib/python3.10/site-packages/rest_framework/viewsets.py", line 125, in view
    return self.dispatch(request, *args, **kwargs)
  File "/usr/local/lib/python3.10/site-packages/rest_framework/views.py", line 509, in dispatch
    response = self.handle_exception(exc)
  File "/usr/local/lib/python3.10/site-packages/rest_framework/views.py", line 469, in handle_exception
    self.raise_uncaught_exception(exc)
  File "/usr/local/lib/python3.10/site-packages/rest_framework/views.py", line 480, in raise_uncaught_exception
    raise exc
  File "/usr/local/lib/python3.10/site-packages/rest_framework/views.py", line 506, in dispatch
    response = handler(request, *args, **kwargs)
  File "/usr/local/lib/python3.10/site-packages/rest_framework/mixins.py", line 43, in list
    return self.get_paginated_response(serializer.data)
  File "/usr/local/lib/python3.10/site-packages/rest_framework/serializers.py", line 768, in data
    ret = super().data
  File "/usr/local/lib/python3.10/site-packages/rest_framework/serializers.py", line 253, in data
    self._data = self.to_representation(self.instance)
  File "/usr/local/lib/python3.10/site-packages/rest_framework/serializers.py", line 686, in to_representation
    return [
  File "/usr/local/lib/python3.10/site-packages/rest_framework/serializers.py", line 687, in <listcomp>
    self.child.to_representation(item) for item in iterable
  File "/usr/local/lib/python3.10/site-packages/rest_framework/serializers.py", line 522, in to_representation
    ret[field.field_name] = field.to_representation(attribute)
  File "/usr/local/lib/python3.10/site-packages/rest_framework/fields.py", line 1838, in to_representation
    return method(value)
  File "/app/enterprise_data_system/core/serializers.py", line 61, in get_customer_name
    return f"{obj.customer.first_name} {obj.customer.last_name}" if obj.customer else None
AttributeError: 'Contract' object has no attribute 'customer'
"GET /api/contracts/ HTTP/1.1" 500 127897
Watching for file changes with StatReloader
Internal Server Error: /api/contracts/
Traceback (most recent call last):
  File "/usr/local/lib/python3.10/site-packages/django/core/handlers/exception.py", line 55, in inner
    response = get_response(request)
  File "/usr/local/lib/python3.10/site-packages/django/core/handlers/base.py", line 197, in _get_response
    response = wrapped_callback(request, *callback_args, **callback_kwargs)
  File "/usr/local/lib/python3.10/site-packages/django/views/decorators/csrf.py", line 56, in wrapper_view
    return view_func(*args, **kwargs)
  File "/usr/local/lib/python3.10/site-packages/rest_framework/viewsets.py", line 125, in view
    return self.dispatch(request, *args, **kwargs)
  File "/usr/local/lib/python3.10/site-packages/rest_framework/views.py", line 509, in dispatch
    response = self.handle_exception(exc)
  File "/usr/local/lib/python3.10/site-packages/rest_framework/views.py", line 469, in handle_exception
    self.raise_uncaught_exception(exc)
  File "/usr/local/lib/python3.10/site-packages/rest_framework/views.py", line 480, in raise_uncaught_exception
    raise exc
  File "/usr/local/lib/python3.10/site-packages/rest_framework/views.py", line 506, in dispatch
    response = handler(request, *args, **kwargs)
  File "/usr/local/lib/python3.10/site-packages/rest_framework/mixins.py", line 43, in list
    return self.get_paginated_response(serializer.data)
  File "/usr/local/lib/python3.10/site-packages/rest_framework/serializers.py", line 768, in data
    ret = super().data
  File "/usr/local/lib/python3.10/site-packages/rest_framework/serializers.py", line 253, in data
    self._data = self.to_representation(self.instance)
  File "/usr/local/lib/python3.10/site-packages/rest_framework/serializers.py", line 686, in to_representation
    return [
  File "/usr/local/lib/python3.10/site-packages/rest_framework/serializers.py", line 687, in <listcomp>
    self.child.to_representation(item) for item in iterable
  File "/usr/local/lib/python3.10/site-packages/rest_framework/serializers.py", line 522, in to_representation
    ret[field.field_name] = field.to_representation(attribute)
  File "/usr/local/lib/python3.10/site-packages/rest_framework/fields.py", line 1838, in to_representation
    return method(value)
  File "/app/enterprise_data_system/core/serializers.py", line 61, in get_customer_name
    return f"{obj.customer.first_name} {obj.customer.last_name}" if obj.customer else None
AttributeError: 'Contract' object has no attribute 'customer'
"GET /api/contracts/ HTTP/1.1" 500 127897
Internal Server Error: /api/contracts/
Traceback (most recent call last):
  File "/usr/local/lib/python3.10/site-packages/django/core/handlers/exception.py", line 55, in inner
    response = get_response(request)
  File "/usr/local/lib/python3.10/site-packages/django/core/handlers/base.py", line 197, in _get_response
    response = wrapped_callback(request, *callback_args, **callback_kwargs)
  File "/usr/local/lib/python3.10/site-packages/django/views/decorators/csrf.py", line 56, in wrapper_view
    return view_func(*args, **kwargs)
  File "/usr/local/lib/python3.10/site-packages/rest_framework/viewsets.py", line 125, in view
    return self.dispatch(request, *args, **kwargs)
  File "/usr/local/lib/python3.10/site-packages/rest_framework/views.py", line 509, in dispatch
    response = self.handle_exception(exc)
  File "/usr/local/lib/python3.10/site-packages/rest_framework/views.py", line 469, in handle_exception
    self.raise_uncaught_exception(exc)
  File "/usr/local/lib/python3.10/site-packages/rest_framework/views.py", line 480, in raise_uncaught_exception
    raise exc
  File "/usr/local/lib/python3.10/site-packages/rest_framework/views.py", line 506, in dispatch
    response = handler(request, *args, **kwargs)
  File "/usr/local/lib/python3.10/site-packages/rest_framework/mixins.py", line 43, in list
    return self.get_paginated_response(serializer.data)
  File "/usr/local/lib/python3.10/site-packages/rest_framework/serializers.py", line 768, in data
    ret = super().data
  File "/usr/local/lib/python3.10/site-packages/rest_framework/serializers.py", line 253, in data
    self._data = self.to_representation(self.instance)
  File "/usr/local/lib/python3.10/site-packages/rest_framework/serializers.py", line 686, in to_representation
    return [
  File "/usr/local/lib/python3.10/site-packages/rest_framework/serializers.py", line 687, in <listcomp>
    self.child.to_representation(item) for item in iterable
  File "/usr/local/lib/python3.10/site-packages/rest_framework/serializers.py", line 522, in to_representation
    ret[field.field_name] = field.to_representation(attribute)
  File "/usr/local/lib/python3.10/site-packages/rest_framework/fields.py", line 1838, in to_representation
    return method(value)
  File "/app/enterprise_data_system/core/serializers.py", line 61, in get_customer_name
    return f"{obj.customer.first_name} {obj.customer.last_name}" if obj.customer else None
AttributeError: 'Contract' object has no attribute 'customer'
"GET /api/contracts/ HTTP/1.1" 500 127897
Internal Server Error: /api/contracts/
Traceback (most recent call last):
  File "/usr/local/lib/python3.10/site-packages/django/core/handlers/exception.py", line 55, in inner
    response = get_response(request)
  File "/usr/local/lib/python3.10/site-packages/django/core/handlers/base.py", line 197, in _get_response
    response = wrapped_callback(request, *callback_args, **callback_kwargs)
  File "/usr/local/lib/python3.10/site-packages/django/views/decorators/csrf.py", line 56, in wrapper_view
    return view_func(*args, **kwargs)
  File "/usr/local/lib/python3.10/site-packages/rest_framework/viewsets.py", line 125, in view
    return self.dispatch(request, *args, **kwargs)
  File "/usr/local/lib/python3.10/site-packages/rest_framework/views.py", line 509, in dispatch
    response = self.handle_exception(exc)
  File "/usr/local/lib/python3.10/site-packages/rest_framework/views.py", line 469, in handle_exception
    self.raise_uncaught_exception(exc)
  File "/usr/local/lib/python3.10/site-packages/rest_framework/views.py", line 480, in raise_uncaught_exception
    raise exc
  File "/usr/local/lib/python3.10/site-packages/rest_framework/views.py", line 506, in dispatch
    response = handler(request, *args, **kwargs)
  File "/usr/local/lib/python3.10/site-packages/rest_framework/mixins.py", line 43, in list
    return self.get_paginated_response(serializer.data)
  File "/usr/local/lib/python3.10/site-packages/rest_framework/serializers.py", line 768, in data
    ret = super().data
  File "/usr/local/lib/python3.10/site-packages/rest_framework/serializers.py", line 253, in data
    self._data = self.to_representation(self.instance)
  File "/usr/local/lib/python3.10/site-packages/rest_framework/serializers.py", line 686, in to_representation
    return [
  File "/usr/local/lib/python3.10/site-packages/rest_framework/serializers.py", line 687, in <listcomp>
    self.child.to_representation(item) for item in iterable
  File "/usr/local/lib/python3.10/site-packages/rest_framework/serializers.py", line 522, in to_representation
    ret[field.field_name] = field.to_representation(attribute)
  File "/usr/local/lib/python3.10/site-packages/rest_framework/fields.py", line 1838, in to_representation
    return method(value)
  File "/app/enterprise_data_system/core/serializers.py", line 61, in get_customer_name
    return f"{obj.customer.first_name} {obj.customer.last_name}" if obj.customer else None
AttributeError: 'Contract' object has no attribute 'customer'
"GET /api/contracts/ HTTP/1.1" 500 127897
/app/enterprise_data_system/core/serializers.py changed, reloading.
Watching for file changes with StatReloader
"OPTIONS /api/contracts/ HTTP/1.1" 200 0
"GET /api/contracts/ HTTP/1.1" 200 1852
/app/enterprise_data_system/core/serializers.py changed, reloading.
Watching for file changes with StatReloader
Internal Server Error: /api/contracts/
Traceback (most recent call last):
  File "/usr/local/lib/python3.10/site-packages/django/core/handlers/exception.py", line 55, in inner
    response = get_response(request)
  File "/usr/local/lib/python3.10/site-packages/django/core/handlers/base.py", line 197, in _get_response
    response = wrapped_callback(request, *callback_args, **callback_kwargs)
  File "/usr/local/lib/python3.10/site-packages/django/views/decorators/csrf.py", line 56, in wrapper_view
    return view_func(*args, **kwargs)
  File "/usr/local/lib/python3.10/site-packages/rest_framework/viewsets.py", line 125, in view
    return self.dispatch(request, *args, **kwargs)
  File "/usr/local/lib/python3.10/site-packages/rest_framework/views.py", line 509, in dispatch
    response = self.handle_exception(exc)
  File "/usr/local/lib/python3.10/site-packages/rest_framework/views.py", line 469, in handle_exception
    self.raise_uncaught_exception(exc)
  File "/usr/local/lib/python3.10/site-packages/rest_framework/views.py", line 480, in raise_uncaught_exception
    raise exc
  File "/usr/local/lib/python3.10/site-packages/rest_framework/views.py", line 506, in dispatch
    response = handler(request, *args, **kwargs)
  File "/usr/local/lib/python3.10/site-packages/rest_framework/mixins.py", line 43, in list
    return self.get_paginated_response(serializer.data)
  File "/usr/local/lib/python3.10/site-packages/rest_framework/serializers.py", line 768, in data
    ret = super().data
  File "/usr/local/lib/python3.10/site-packages/rest_framework/serializers.py", line 253, in data
    self._data = self.to_representation(self.instance)
  File "/usr/local/lib/python3.10/site-packages/rest_framework/serializers.py", line 686, in to_representation
    return [
  File "/usr/local/lib/python3.10/site-packages/rest_framework/serializers.py", line 687, in <listcomp>
    self.child.to_representation(item) for item in iterable
  File "/usr/local/lib/python3.10/site-packages/rest_framework/serializers.py", line 522, in to_representation
    ret[field.field_name] = field.to_representation(attribute)
  File "/usr/local/lib/python3.10/site-packages/rest_framework/fields.py", line 1838, in to_representation
    return method(value)
  File "/app/enterprise_data_system/core/serializers.py", line 68, in get_customer_name
    latest_invoice = obj.account.invoices.order_by('-run_date').first()
AttributeError: 'Account' object has no attribute 'invoices'
"GET /api/contracts/ HTTP/1.1" 500 128281
/app/enterprise_data_system/core/serializers.py changed, reloading.
Watching for file changes with StatReloader
/app/enterprise_data_system/core/serializers.py changed, reloading.
Watching for file changes with StatReloader
"GET /api/contracts/ HTTP/1.1" 200 1700
/app/enterprise_data_system/core/serializers.py changed, reloading.
Watching for file changes with StatReloader
/app/enterprise_data_system/core/serializers.py changed, reloading.
Watching for file changes with StatReloader
"GET /api/contracts/ HTTP/1.1" 200 1700
"GET /api/contracts/ HTTP/1.1" 200 1700
/app/enterprise_data_system/core/serializers.py changed, reloading.
Watching for file changes with StatReloader
"GET /api/contracts/ HTTP/1.1" 200 1812
"GET /api/contracts/ HTTP/1.1" 200 1812
/app/enterprise_data_system/core/views.py changed, reloading.
Watching for file changes with StatReloader
"GET /api/contracts/ HTTP/1.1" 200 1812
"GET /api/contracts/ HTTP/1.1" 200 1812
"GET /api/contracts/ HTTP/1.1" 200 1812
/app/enterprise_data_system/core/views.py changed, reloading.
Watching for file changes with StatReloader
/app/enterprise_data_system/core/serializers.py changed, reloading.
Watching for file changes with StatReloader
/app/enterprise_data_system/core/views.py changed, reloading.
Watching for file changes with StatReloader
/app/enterprise_data_system/core/serializers.py changed, reloading.
Watching for file changes with StatReloader
/app/enterprise_data_system/core/serializers.py changed, reloading.
Watching for file changes with StatReloader
"GET /api/contracts/ HTTP/1.1" 200 1812
"GET /api/contracts/ HTTP/1.1" 200 1812
/app/enterprise_data_system/core/serializers.py changed, reloading.
Watching for file changes with StatReloader
"GET /api/contracts/ HTTP/1.1" 200 1812
"GET /api/contracts/ HTTP/1.1" 200 1812
"GET /api/contracts/ HTTP/1.1" 200 1812
"GET /api/contracts/ HTTP/1.1" 200 1812
/app/enterprise_data_system/core/serializers.py changed, reloading.
Watching for file changes with StatReloader
"GET /api/contracts/ HTTP/1.1" 200 1812
/app/enterprise_data_system/core/serializers.py changed, reloading.
Watching for file changes with StatReloader
/app/enterprise_data_system/core/serializers.py changed, reloading.
Watching for file changes with StatReloader
"GET /api/contracts/ HTTP/1.1" 200 1840
/app/enterprise_data_system/core/models/account_models.py changed, reloading.
Watching for file changes with StatReloader
Watching for file changes with StatReloader
Internal Server Error: /api/contracts/
Traceback (most recent call last):
  File "/usr/local/lib/python3.10/site-packages/django/db/backends/utils.py", line 89, in _execute
    return self.cursor.execute(sql, params)
psycopg2.errors.UndefinedColumn: column account.customer_id does not exist
LINE 1: ...s"."id", "lineofbusiness"."name", "account"."id", "account"....
                                                             ^


The above exception was the direct cause of the following exception:

Traceback (most recent call last):
  File "/usr/local/lib/python3.10/site-packages/django/core/handlers/exception.py", line 55, in inner
    response = get_response(request)
  File "/usr/local/lib/python3.10/site-packages/django/core/handlers/base.py", line 197, in _get_response
    response = wrapped_callback(request, *callback_args, **callback_kwargs)
  File "/usr/local/lib/python3.10/site-packages/django/views/decorators/csrf.py", line 56, in wrapper_view
    return view_func(*args, **kwargs)
  File "/usr/local/lib/python3.10/site-packages/rest_framework/viewsets.py", line 125, in view
    return self.dispatch(request, *args, **kwargs)
  File "/usr/local/lib/python3.10/site-packages/rest_framework/views.py", line 509, in dispatch
    response = self.handle_exception(exc)
  File "/usr/local/lib/python3.10/site-packages/rest_framework/views.py", line 469, in handle_exception
    self.raise_uncaught_exception(exc)
  File "/usr/local/lib/python3.10/site-packages/rest_framework/views.py", line 480, in raise_uncaught_exception
    raise exc
  File "/usr/local/lib/python3.10/site-packages/rest_framework/views.py", line 506, in dispatch
    response = handler(request, *args, **kwargs)
  File "/usr/local/lib/python3.10/site-packages/rest_framework/mixins.py", line 40, in list
    page = self.paginate_queryset(queryset)
  File "/usr/local/lib/python3.10/site-packages/rest_framework/generics.py", line 171, in paginate_queryset
    return self.paginator.paginate_queryset(queryset, self.request, view=self)
  File "/usr/local/lib/python3.10/site-packages/rest_framework/pagination.py", line 216, in paginate_queryset
    return list(self.page)
  File "/usr/local/lib/python3.10/site-packages/django/core/paginator.py", line 174, in __len__
    return len(self.object_list)
  File "/usr/local/lib/python3.10/site-packages/django/db/models/query.py", line 380, in __len__
    self._fetch_all()
  File "/usr/local/lib/python3.10/site-packages/django/db/models/query.py", line 1881, in _fetch_all
    self._result_cache = list(self._iterable_class(self))
  File "/usr/local/lib/python3.10/site-packages/django/db/models/query.py", line 91, in __iter__
    results = compiler.execute_sql(
  File "/usr/local/lib/python3.10/site-packages/django/db/models/sql/compiler.py", line 1562, in execute_sql
    cursor.execute(sql, params)
  File "/usr/local/lib/python3.10/site-packages/django/db/backends/utils.py", line 102, in execute
    return super().execute(sql, params)
  File "/usr/local/lib/python3.10/site-packages/django/db/backends/utils.py", line 67, in execute
    return self._execute_with_wrappers(
  File "/usr/local/lib/python3.10/site-packages/django/db/backends/utils.py", line 80, in _execute_with_wrappers
    return executor(sql, params, many, context)
  File "/usr/local/lib/python3.10/site-packages/django/db/backends/utils.py", line 84, in _execute
    with self.db.wrap_database_errors:
  File "/usr/local/lib/python3.10/site-packages/django/db/utils.py", line 91, in __exit__
    raise dj_exc_value.with_traceback(traceback) from exc_value
  File "/usr/local/lib/python3.10/site-packages/django/db/backends/utils.py", line 89, in _execute
    return self.cursor.execute(sql, params)
django.db.utils.ProgrammingError: column account.customer_id does not exist
LINE 1: ...s"."id", "lineofbusiness"."name", "account"."id", "account"....
                                                             ^

"GET /api/contracts/ HTTP/1.1" 500 161769
Internal Server Error: /api/contracts/
Traceback (most recent call last):
  File "/usr/local/lib/python3.10/site-packages/django/db/backends/utils.py", line 89, in _execute
    return self.cursor.execute(sql, params)
psycopg2.errors.UndefinedColumn: column account.customer_id does not exist
LINE 1: ...s"."id", "lineofbusiness"."name", "account"."id", "account"....
                                                             ^


The above exception was the direct cause of the following exception:

Traceback (most recent call last):
  File "/usr/local/lib/python3.10/site-packages/django/core/handlers/exception.py", line 55, in inner
    response = get_response(request)
  File "/usr/local/lib/python3.10/site-packages/django/core/handlers/base.py", line 197, in _get_response
    response = wrapped_callback(request, *callback_args, **callback_kwargs)
  File "/usr/local/lib/python3.10/site-packages/django/views/decorators/csrf.py", line 56, in wrapper_view
    return view_func(*args, **kwargs)
  File "/usr/local/lib/python3.10/site-packages/rest_framework/viewsets.py", line 125, in view
    return self.dispatch(request, *args, **kwargs)
  File "/usr/local/lib/python3.10/site-packages/rest_framework/views.py", line 509, in dispatch
    response = self.handle_exception(exc)
  File "/usr/local/lib/python3.10/site-packages/rest_framework/views.py", line 469, in handle_exception
    self.raise_uncaught_exception(exc)
  File "/usr/local/lib/python3.10/site-packages/rest_framework/views.py", line 480, in raise_uncaught_exception
    raise exc
  File "/usr/local/lib/python3.10/site-packages/rest_framework/views.py", line 506, in dispatch
    response = handler(request, *args, **kwargs)
  File "/usr/local/lib/python3.10/site-packages/rest_framework/mixins.py", line 40, in list
    page = self.paginate_queryset(queryset)
  File "/usr/local/lib/python3.10/site-packages/rest_framework/generics.py", line 171, in paginate_queryset
    return self.paginator.paginate_queryset(queryset, self.request, view=self)
  File "/usr/local/lib/python3.10/site-packages/rest_framework/pagination.py", line 216, in paginate_queryset
    return list(self.page)
  File "/usr/local/lib/python3.10/site-packages/django/core/paginator.py", line 174, in __len__
    return len(self.object_list)
  File "/usr/local/lib/python3.10/site-packages/django/db/models/query.py", line 380, in __len__
    self._fetch_all()
  File "/usr/local/lib/python3.10/site-packages/django/db/models/query.py", line 1881, in _fetch_all
    self._result_cache = list(self._iterable_class(self))
  File "/usr/local/lib/python3.10/site-packages/django/db/models/query.py", line 91, in __iter__
    results = compiler.execute_sql(
  File "/usr/local/lib/python3.10/site-packages/django/db/models/sql/compiler.py", line 1562, in execute_sql
    cursor.execute(sql, params)
  File "/usr/local/lib/python3.10/site-packages/django/db/backends/utils.py", line 102, in execute
    return super().execute(sql, params)
  File "/usr/local/lib/python3.10/site-packages/django/db/backends/utils.py", line 67, in execute
    return self._execute_with_wrappers(
  File "/usr/local/lib/python3.10/site-packages/django/db/backends/utils.py", line 80, in _execute_with_wrappers
    return executor(sql, params, many, context)
  File "/usr/local/lib/python3.10/site-packages/django/db/backends/utils.py", line 84, in _execute
    with self.db.wrap_database_errors:
  File "/usr/local/lib/python3.10/site-packages/django/db/utils.py", line 91, in __exit__
    raise dj_exc_value.with_traceback(traceback) from exc_value
  File "/usr/local/lib/python3.10/site-packages/django/db/backends/utils.py", line 89, in _execute
    return self.cursor.execute(sql, params)
django.db.utils.ProgrammingError: column account.customer_id does not exist
LINE 1: ...s"."id", "lineofbusiness"."name", "account"."id", "account"....
                                                             ^

"GET /api/contracts/ HTTP/1.1" 500 161769
Unauthorized: /api/contracts/
"GET /api/contracts/ HTTP/1.1" 401 51
"OPTIONS /auth/login/ HTTP/1.1" 200 0
Unauthorized: /auth/login/
"POST /auth/login/ HTTP/1.1" 401 36
Unauthorized: /auth/login/
"POST /auth/login/ HTTP/1.1" 401 36
Unauthorized: /auth/login/
"POST /auth/login/ HTTP/1.1" 401 36
/app/enterprise_data_system/core/views.py changed, reloading.
Watching for file changes with StatReloader
Watching for file changes with StatReloader
Not Found: /api/analytics/ai/
"GET /api/analytics/ai/ HTTP/1.1" 404 5855
Unauthorized: /auth/login/
"POST /auth/login/ HTTP/1.1" 401 36
Unauthorized: /auth/login/
"POST /auth/login/ HTTP/1.1" 401 36
Watching for file changes with StatReloader
Not Found: /api/analytics/ai/
"GET /api/analytics/ai/ HTTP/1.1" 404 5855
Unauthorized: /auth/login/
"POST /auth/login/ HTTP/1.1" 401 36
/app/enterprise_data_system/enterprise_data_system/urls.py changed, reloading.
Watching for file changes with StatReloader
/app/enterprise_data_system/enterprise_data_system/urls.py changed, reloading.
Watching for file changes with StatReloader
Unauthorized: /auth/login/
"POST /auth/login/ HTTP/1.1" 401 36
Watching for file changes with StatReloader
Internal Server Error: /api/analytics/ai/
"GET /api/analytics/ai/ HTTP/1.1" 500 159
/app/enterprise_data_system/core/views.py changed, reloading.
Watching for file changes with StatReloader
Watching for file changes with StatReloader
"GET /api/analytics/ai/ HTTP/1.1" 200 583
Unauthorized: /auth/login/
"POST /auth/login/ HTTP/1.1" 401 36
"POST /auth/login/ HTTP/1.1" 200 517
"GET /api/analytics/ai/ HTTP/1.1" 200 583
Unauthorized: /auth/login/
"POST /auth/login/ HTTP/1.1" 401 36
"OPTIONS /auth/login/ HTTP/1.1" 200 0
"POST /auth/login/ HTTP/1.1" 200 517
"OPTIONS /api/analytics/ai/ HTTP/1.1" 200 0
"GET /api/analytics/ai/ HTTP/1.1" 200 583
Unauthorized: /auth/login/
"POST /auth/login/ HTTP/1.1" 401 36
Unauthorized: /auth/login/
"POST /auth/login/ HTTP/1.1" 401 36
"POST /auth/login/ HTTP/1.1" 200 517
"OPTIONS /api/customers/ HTTP/1.1" 200 0
"OPTIONS /api/contracts/analytics/ HTTP/1.1" 200 0
"OPTIONS /api/activities/ HTTP/1.1" 200 0
Not Found: /api/activities/
"GET /api/activities/ HTTP/1.1" 404 5987
"GET /api/contracts/analytics/ HTTP/1.1" 200 203
"GET /api/customers/ HTTP/1.1" 200 2690
/app/enterprise_data_system/enterprise_data_system/urls.py changed, reloading.
Watching for file changes with StatReloader
Watching for file changes with StatReloader
"GET /api/analytics/ai/ HTTP/1.1" 200 583
Not Found: /api/activities/
"GET /api/activities/ HTTP/1.1" 404 5987
"GET /api/contracts/analytics/ HTTP/1.1" 200 203
"GET /api/customers/ HTTP/1.1" 200 2690
Watching for file changes with StatReloader
"GET /api/customers/ HTTP/1.1" 200 2690
"OPTIONS /api/analytics/ai/ HTTP/1.1" 200 0
"GET /api/analytics/ai/ HTTP/1.1" 200 583
"OPTIONS /api/analytics/dashboard/ HTTP/1.1" 200 0
Not Found: /api/analytics/dashboard/
"GET /api/analytics/dashboard/ HTTP/1.1" 404 6014
"OPTIONS /api/contracts/ HTTP/1.1" 200 0
Internal Server Error: /api/contracts/
Traceback (most recent call last):
  File "/usr/local/lib/python3.10/site-packages/django/core/handlers/exception.py", line 55, in inner
    response = get_response(request)
  File "/usr/local/lib/python3.10/site-packages/django/core/handlers/base.py", line 197, in _get_response
    response = wrapped_callback(request, *callback_args, **callback_kwargs)
  File "/usr/local/lib/python3.10/site-packages/django/views/decorators/csrf.py", line 56, in wrapper_view
    return view_func(*args, **kwargs)
  File "/usr/local/lib/python3.10/site-packages/rest_framework/viewsets.py", line 125, in view
    return self.dispatch(request, *args, **kwargs)
  File "/usr/local/lib/python3.10/site-packages/rest_framework/views.py", line 509, in dispatch
    response = self.handle_exception(exc)
  File "/usr/local/lib/python3.10/site-packages/rest_framework/views.py", line 469, in handle_exception
    self.raise_uncaught_exception(exc)
  File "/usr/local/lib/python3.10/site-packages/rest_framework/views.py", line 480, in raise_uncaught_exception
    raise exc
  File "/usr/local/lib/python3.10/site-packages/rest_framework/views.py", line 506, in dispatch
    response = handler(request, *args, **kwargs)
  File "/usr/local/lib/python3.10/site-packages/rest_framework/mixins.py", line 43, in list
    return self.get_paginated_response(serializer.data)
  File "/usr/local/lib/python3.10/site-packages/rest_framework/serializers.py", line 768, in data
    ret = super().data
  File "/usr/local/lib/python3.10/site-packages/rest_framework/serializers.py", line 253, in data
    self._data = self.to_representation(self.instance)
  File "/usr/local/lib/python3.10/site-packages/rest_framework/serializers.py", line 686, in to_representation
    return [
  File "/usr/local/lib/python3.10/site-packages/rest_framework/serializers.py", line 687, in <listcomp>
    self.child.to_representation(item) for item in iterable
  File "/usr/local/lib/python3.10/site-packages/rest_framework/serializers.py", line 522, in to_representation
    ret[field.field_name] = field.to_representation(attribute)
  File "/usr/local/lib/python3.10/site-packages/rest_framework/fields.py", line 1838, in to_representation
    return method(value)
  File "/app/enterprise_data_system/core/serializers.py", line 64, in get_customer
    return f"{customer.first_name} {customer.last_name}"
AttributeError: 'NoneType' object has no attribute 'first_name'
"GET /api/contracts/ HTTP/1.1" 500 128032
"GET /api/customers/ HTTP/1.1" 200 2690
Not Found: /api/analytics/dashboard/
"GET /api/analytics/dashboard/ HTTP/1.1" 404 6014
"GET /api/customers/ HTTP/1.1" 200 2690
"GET /api/customers/ HTTP/1.1" 200 2690
Not Found: /api/analytics/dashboard/
"GET /api/analytics/dashboard/ HTTP/1.1" 404 6014
Not Found: /api/analytics/dashboard/
"GET /api/analytics/dashboard/ HTTP/1.1" 404 6014
Watching for file changes with StatReloader
Not Found: /api/analytics/dashboard/
"GET /api/analytics/dashboard/ HTTP/1.1" 404 6014
"GET /api/customers/ HTTP/1.1" 200 2690
Not Found: /api/activities/
"GET /api/activities/ HTTP/1.1" 404 5987
"GET /api/contracts/analytics/ HTTP/1.1" 200 203
"GET /api/customers/ HTTP/1.1" 200 2690
"POST /auth/login/ HTTP/1.1" 200 517
"GET /api/analytics/ai/ HTTP/1.1" 200 583
Internal Server Error: /api/contracts/
Traceback (most recent call last):
  File "/usr/local/lib/python3.10/site-packages/django/core/handlers/exception.py", line 55, in inner
    response = get_response(request)
  File "/usr/local/lib/python3.10/site-packages/django/core/handlers/base.py", line 197, in _get_response
    response = wrapped_callback(request, *callback_args, **callback_kwargs)
  File "/usr/local/lib/python3.10/site-packages/django/views/decorators/csrf.py", line 56, in wrapper_view
    return view_func(*args, **kwargs)
  File "/usr/local/lib/python3.10/site-packages/rest_framework/viewsets.py", line 125, in view
    return self.dispatch(request, *args, **kwargs)
  File "/usr/local/lib/python3.10/site-packages/rest_framework/views.py", line 509, in dispatch
    response = self.handle_exception(exc)
  File "/usr/local/lib/python3.10/site-packages/rest_framework/views.py", line 469, in handle_exception
    self.raise_uncaught_exception(exc)
  File "/usr/local/lib/python3.10/site-packages/rest_framework/views.py", line 480, in raise_uncaught_exception
    raise exc
  File "/usr/local/lib/python3.10/site-packages/rest_framework/views.py", line 506, in dispatch
    response = handler(request, *args, **kwargs)
  File "/usr/local/lib/python3.10/site-packages/rest_framework/mixins.py", line 43, in list
    return self.get_paginated_response(serializer.data)
  File "/usr/local/lib/python3.10/site-packages/rest_framework/serializers.py", line 768, in data
    ret = super().data
  File "/usr/local/lib/python3.10/site-packages/rest_framework/serializers.py", line 253, in data
    self._data = self.to_representation(self.instance)
  File "/usr/local/lib/python3.10/site-packages/rest_framework/serializers.py", line 686, in to_representation
    return [
  File "/usr/local/lib/python3.10/site-packages/rest_framework/serializers.py", line 687, in <listcomp>
    self.child.to_representation(item) for item in iterable
  File "/usr/local/lib/python3.10/site-packages/rest_framework/serializers.py", line 522, in to_representation
    ret[field.field_name] = field.to_representation(attribute)
  File "/usr/local/lib/python3.10/site-packages/rest_framework/fields.py", line 1838, in to_representation
    return method(value)
  File "/app/enterprise_data_system/core/serializers.py", line 64, in get_customer
    return f"{customer.first_name} {customer.last_name}"
AttributeError: 'NoneType' object has no attribute 'first_name'
"GET /api/contracts/ HTTP/1.1" 500 128032
Not Found: /api/analytics/dashboard/
"GET /api/analytics/dashboard/ HTTP/1.1" 404 6014
"GET /api/analytics/ai/ HTTP/1.1" 200 583
/app/enterprise_data_system/core/views.py changed, reloading.
Watching for file changes with StatReloader
Watching for file changes with StatReloader
"POST /auth/login/ HTTP/1.1" 200 517
"OPTIONS /auth/login/ HTTP/1.1" 200 0
"POST /auth/login/ HTTP/1.1" 200 517
Not Found: /api/activities/
"GET /api/activities/ HTTP/1.1" 404 5987
"GET /api/contracts/analytics/ HTTP/1.1" 200 203
"GET /api/customers/ HTTP/1.1" 200 2690
"GET /api/analytics/ai/ HTTP/1.1" 200 583
Not Found: /api/analytics/dashboard/
"GET /api/analytics/dashboard/ HTTP/1.1" 404 6014
Internal Server Error: /api/contracts/
Traceback (most recent call last):
  File "/usr/local/lib/python3.10/site-packages/django/core/handlers/exception.py", line 55, in inner
    response = get_response(request)
  File "/usr/local/lib/python3.10/site-packages/django/core/handlers/base.py", line 197, in _get_response
    response = wrapped_callback(request, *callback_args, **callback_kwargs)
  File "/usr/local/lib/python3.10/site-packages/django/views/decorators/csrf.py", line 56, in wrapper_view
    return view_func(*args, **kwargs)
  File "/usr/local/lib/python3.10/site-packages/rest_framework/viewsets.py", line 125, in view
    return self.dispatch(request, *args, **kwargs)
  File "/usr/local/lib/python3.10/site-packages/rest_framework/views.py", line 509, in dispatch
    response = self.handle_exception(exc)
  File "/usr/local/lib/python3.10/site-packages/rest_framework/views.py", line 469, in handle_exception
    self.raise_uncaught_exception(exc)
  File "/usr/local/lib/python3.10/site-packages/rest_framework/views.py", line 480, in raise_uncaught_exception
    raise exc
  File "/usr/local/lib/python3.10/site-packages/rest_framework/views.py", line 506, in dispatch
    response = handler(request, *args, **kwargs)
  File "/usr/local/lib/python3.10/site-packages/rest_framework/mixins.py", line 43, in list
    return self.get_paginated_response(serializer.data)
  File "/usr/local/lib/python3.10/site-packages/rest_framework/serializers.py", line 768, in data
    ret = super().data
  File "/usr/local/lib/python3.10/site-packages/rest_framework/serializers.py", line 253, in data
    self._data = self.to_representation(self.instance)
  File "/usr/local/lib/python3.10/site-packages/rest_framework/serializers.py", line 686, in to_representation
    return [
  File "/usr/local/lib/python3.10/site-packages/rest_framework/serializers.py", line 687, in <listcomp>
    self.child.to_representation(item) for item in iterable
  File "/usr/local/lib/python3.10/site-packages/rest_framework/serializers.py", line 522, in to_representation
    ret[field.field_name] = field.to_representation(attribute)
  File "/usr/local/lib/python3.10/site-packages/rest_framework/fields.py", line 1838, in to_representation
    return method(value)
  File "/app/enterprise_data_system/core/serializers.py", line 64, in get_customer
    return f"{customer.first_name} {customer.last_name}"
AttributeError: 'NoneType' object has no attribute 'first_name'
"GET /api/contracts/ HTTP/1.1" 500 128032
"GET /api/customers/ HTTP/1.1" 200 2690
Internal Server Error: /api/contracts/
Traceback (most recent call last):
  File "/usr/local/lib/python3.10/site-packages/django/core/handlers/exception.py", line 55, in inner
    response = get_response(request)
  File "/usr/local/lib/python3.10/site-packages/django/core/handlers/base.py", line 197, in _get_response
    response = wrapped_callback(request, *callback_args, **callback_kwargs)
  File "/usr/local/lib/python3.10/site-packages/django/views/decorators/csrf.py", line 56, in wrapper_view
    return view_func(*args, **kwargs)
  File "/usr/local/lib/python3.10/site-packages/rest_framework/viewsets.py", line 125, in view
    return self.dispatch(request, *args, **kwargs)
  File "/usr/local/lib/python3.10/site-packages/rest_framework/views.py", line 509, in dispatch
    response = self.handle_exception(exc)
  File "/usr/local/lib/python3.10/site-packages/rest_framework/views.py", line 469, in handle_exception
    self.raise_uncaught_exception(exc)
  File "/usr/local/lib/python3.10/site-packages/rest_framework/views.py", line 480, in raise_uncaught_exception
    raise exc
  File "/usr/local/lib/python3.10/site-packages/rest_framework/views.py", line 506, in dispatch
    response = handler(request, *args, **kwargs)
  File "/usr/local/lib/python3.10/site-packages/rest_framework/mixins.py", line 43, in list
    return self.get_paginated_response(serializer.data)
  File "/usr/local/lib/python3.10/site-packages/rest_framework/serializers.py", line 768, in data
    ret = super().data
  File "/usr/local/lib/python3.10/site-packages/rest_framework/serializers.py", line 253, in data
    self._data = self.to_representation(self.instance)
  File "/usr/local/lib/python3.10/site-packages/rest_framework/serializers.py", line 686, in to_representation
    return [
  File "/usr/local/lib/python3.10/site-packages/rest_framework/serializers.py", line 687, in <listcomp>
    self.child.to_representation(item) for item in iterable
  File "/usr/local/lib/python3.10/site-packages/rest_framework/serializers.py", line 522, in to_representation
    ret[field.field_name] = field.to_representation(attribute)
  File "/usr/local/lib/python3.10/site-packages/rest_framework/fields.py", line 1838, in to_representation
    return method(value)
  File "/app/enterprise_data_system/core/serializers.py", line 64, in get_customer
    return f"{customer.first_name} {customer.last_name}"
AttributeError: 'NoneType' object has no attribute 'first_name'
"GET /api/contracts/ HTTP/1.1" 500 128032
Not Found: /api/analytics/dashboard/
"GET /api/analytics/dashboard/ HTTP/1.1" 404 6014
Not Found: /api/activities/
"GET /api/activities/ HTTP/1.1" 404 5987
"GET /api/customers/ HTTP/1.1" 200 2690
"GET /api/contracts/analytics/ HTTP/1.1" 200 203
Not Found: /api/activities/
"GET /api/activities/ HTTP/1.1" 404 5987
"GET /api/contracts/analytics/ HTTP/1.1" 200 203
"GET /api/customers/ HTTP/1.1" 200 2690
Not Found: /api/activities/
"GET /api/activities/ HTTP/1.1" 404 5987
"GET /api/contracts/analytics/ HTTP/1.1" 200 203
"GET /api/customers/ HTTP/1.1" 200 2690
Not Found: /api/activities/
"GET /api/activities/ HTTP/1.1" 404 5987
"GET /api/contracts/analytics/ HTTP/1.1" 200 203
"GET /api/customers/ HTTP/1.1" 200 2690
Watching for file changes with StatReloader
Not Found: /api/activities/
"GET /api/activities/ HTTP/1.1" 404 5987
"GET /api/contracts/analytics/ HTTP/1.1" 200 203
"GET /api/customers/ HTTP/1.1" 200 2690
Not Found: /api/activities/
"GET /api/activities/ HTTP/1.1" 404 5987
"GET /api/contracts/analytics/ HTTP/1.1" 200 203
"GET /api/customers/ HTTP/1.1" 200 2690
Not Found: /api/activities/
"GET /api/activities/ HTTP/1.1" 404 5987
"GET /api/contracts/analytics/ HTTP/1.1" 200 203
"GET /api/customers/ HTTP/1.1" 200 2690
Not Found: /api/activities/
"GET /api/activities/ HTTP/1.1" 404 5987
"GET /api/contracts/analytics/ HTTP/1.1" 200 203
"GET /api/customers/ HTTP/1.1" 200 2690
/app/enterprise_data_system/core/serializers.py changed, reloading.
Watching for file changes with StatReloader
Not Found: /api/activities/
"GET /api/activities/ HTTP/1.1" 404 5987
"GET /api/contracts/analytics/ HTTP/1.1" 200 203
"GET /api/customers/ HTTP/1.1" 200 2690
/app/enterprise_data_system/core/views.py changed, reloading.
Watching for file changes with StatReloader
Watching for file changes with StatReloader
"OPTIONS /api/contracts/analytics/ HTTP/1.1" 200 0
"OPTIONS /api/activities/ HTTP/1.1" 200 0
"OPTIONS /api/customers/ HTTP/1.1" 200 0
Not Found: /api/activities/
"GET /api/activities/ HTTP/1.1" 404 5987
"GET /api/contracts/analytics/ HTTP/1.1" 200 203
"GET /api/customers/ HTTP/1.1" 200 2690
Not Found: /api/activities/
"GET /api/activities/ HTTP/1.1" 404 5987
"GET /api/contracts/analytics/ HTTP/1.1" 200 203
"GET /api/customers/ HTTP/1.1" 200 2690
Not Found: /api/activities/
"GET /api/activities/ HTTP/1.1" 404 5987
"GET /api/contracts/analytics/ HTTP/1.1" 200 203
"GET /api/customers/ HTTP/1.1" 200 2690
"OPTIONS /api/analytics/ai/ HTTP/1.1" 200 0
"GET /api/analytics/ai/ HTTP/1.1" 200 583
"OPTIONS /api/analytics/dashboard/ HTTP/1.1" 200 0
Not Found: /api/analytics/dashboard/
"GET /api/analytics/dashboard/ HTTP/1.1" 404 6014
"OPTIONS /api/contracts/ HTTP/1.1" 200 0
"GET /api/contracts/ HTTP/1.1" 200 1865
"GET /api/customers/ HTTP/1.1" 200 2690
Not Found: /api/analytics/dashboard/
"GET /api/analytics/dashboard/ HTTP/1.1" 404 6014
Not Found: /api/analytics/dashboard/
"GET /api/analytics/dashboard/ HTTP/1.1" 404 6014
Not Found: /api/analytics/dashboard/
"GET /api/analytics/dashboard/ HTTP/1.1" 404 6014
Not Found: /api/analytics/dashboard/
"GET /api/analytics/dashboard/ HTTP/1.1" 404 6014
Not Found: /api/analytics/dashboard/
"GET /api/analytics/dashboard/ HTTP/1.1" 404 6014
Not Found: /api/analytics/dashboard/
"GET /api/analytics/dashboard/ HTTP/1.1" 404 6014
/app/enterprise_data_system/core/views.py changed, reloading.
Watching for file changes with StatReloader
Not Found: /api/analytics/dashboard/
"GET /api/analytics/dashboard/ HTTP/1.1" 404 6014
Not Found: /api/analytics/dashboard/
"GET /api/analytics/dashboard/ HTTP/1.1" 404 6014
Watching for file changes with StatReloader
Not Found: /api/analytics/dashboard/
"GET /api/analytics/dashboard/ HTTP/1.1" 404 6014
Not Found: /api/analytics/dashboard/
"GET /api/analytics/dashboard/ HTTP/1.1" 404 6014
Not Found: /api/analytics/dashboard/
"GET /api/analytics/dashboard/ HTTP/1.1" 404 6014
Not Found: /api/analytics/dashboard/
"GET /api/analytics/dashboard/ HTTP/1.1" 404 6014
Not Found: /api/analytics/dashboard/
"GET /api/analytics/dashboard/ HTTP/1.1" 404 6014
Not Found: /api/analytics/dashboard/
"GET /api/analytics/dashboard/ HTTP/1.1" 404 6014
/app/enterprise_data_system/core/views.py changed, reloading.
Watching for file changes with StatReloader
Watching for file changes with StatReloader
/app/enterprise_data_system/core/models/contract_models.py changed, reloading.
Watching for file changes with StatReloader
Not Found: /api/analytics/dashboard/
"GET /api/analytics/dashboard/ HTTP/1.1" 404 6014
Watching for file changes with StatReloader
Not Found: /api/analytics/dashboard/
"GET /api/analytics/dashboard/ HTTP/1.1" 404 6014
Not Found: /api/analytics/dashboard/
"GET /api/analytics/dashboard/ HTTP/1.1" 404 6014
Not Found: /api/analytics/dashboard/
"GET /api/analytics/dashboard/ HTTP/1.1" 404 6014
Not Found: /api/analytics/dashboard/
"GET /api/analytics/dashboard/ HTTP/1.1" 404 6014
Not Found: /api/analytics/dashboard/
"GET /api/analytics/dashboard/ HTTP/1.1" 404 6014
/app/enterprise_data_system/core/serializers.py changed, reloading.
Watching for file changes with StatReloader
Watching for file changes with StatReloader
Not Found: /api/analytics/dashboard/
"GET /api/analytics/dashboard/ HTTP/1.1" 404 6014
Not Found: /api/analytics/dashboard/
"GET /api/analytics/dashboard/ HTTP/1.1" 404 6014
Not Found: /api/analytics/dashboard/
"GET /api/analytics/dashboard/ HTTP/1.1" 404 6014
Not Found: /api/analytics/dashboard/
"GET /api/analytics/dashboard/ HTTP/1.1" 404 6014
/app/enterprise_data_system/core/views.py changed, reloading.
Watching for file changes with StatReloader
Not Found: /api/analytics/dashboard/
"GET /api/analytics/dashboard/ HTTP/1.1" 404 6014
Not Found: /api/analytics/dashboard/
"GET /api/analytics/dashboard/ HTTP/1.1" 404 6014
Watching for file changes with StatReloader
Not Found: /api/analytics/dashboard/
"GET /api/analytics/dashboard/ HTTP/1.1" 404 6014
Not Found: /api/analytics/dashboard/
"GET /api/analytics/dashboard/ HTTP/1.1" 404 6014
/app/enterprise_data_system/core/serializers.py changed, reloading.
Watching for file changes with StatReloader
Watching for file changes with StatReloader
Not Found: /api/analytics/dashboard/
"GET /api/analytics/dashboard/ HTTP/1.1" 404 6014
Not Found: /api/analytics/dashboard/
"GET /api/analytics/dashboard/ HTTP/1.1" 404 6014
Not Found: /api/analytics/dashboard/
"GET /api/analytics/dashboard/ HTTP/1.1" 404 6014
Not Found: /api/analytics/dashboard/
"GET /api/analytics/dashboard/ HTTP/1.1" 404 6014
Not Found: /api/analytics/dashboard/
"GET /api/analytics/dashboard/ HTTP/1.1" 404 6014
/app/enterprise_data_system/core/views.py changed, reloading.
Watching for file changes with StatReloader
Watching for file changes with StatReloader
Not Found: /api/analytics/dashboard/
"GET /api/analytics/dashboard/ HTTP/1.1" 404 6014
Not Found: /api/analytics/dashboard/
"GET /api/analytics/dashboard/ HTTP/1.1" 404 6014
/app/enterprise_data_system/core/models/account_models.py changed, reloading.
Watching for file changes with StatReloader
/app/enterprise_data_system/core/serializers.py changed, reloading.
Watching for file changes with StatReloader
Watching for file changes with StatReloader
/app/enterprise_data_system/core/views.py changed, reloading.
Watching for file changes with StatReloader
Watching for file changes with StatReloader
Not Found: /api/analytics/dashboard/
"GET /api/analytics/dashboard/ HTTP/1.1" 404 6014
Not Found: /api/analytics/dashboard/
"GET /api/analytics/dashboard/ HTTP/1.1" 404 6014
"GET /api/contracts/ HTTP/1.1" 200 419
/app/enterprise_data_system/core/views.py changed, reloading.
Watching for file changes with StatReloader
Watching for file changes with StatReloader
"OPTIONS /api/analytics/dashboard/ HTTP/1.1" 200 0
Not Found: /api/analytics/dashboard/
"GET /api/analytics/dashboard/ HTTP/1.1" 404 6014
/app/enterprise_data_system/core/serializers.py changed, reloading.
Watching for file changes with StatReloader
Watching for file changes with StatReloader
Not Found: /api/analytics/dashboard/
"GET /api/analytics/dashboard/ HTTP/1.1" 404 6014
"GET /api/contracts/ HTTP/1.1" 200 453
Not Found: /api/analytics/dashboard/
"GET /api/analytics/dashboard/ HTTP/1.1" 404 6014
Not Found: /api/analytics/dashboard/
"GET /api/analytics/dashboard/ HTTP/1.1" 404 6014
Not Found: /api/analytics/dashboard/
"GET /api/analytics/dashboard/ HTTP/1.1" 404 6014
Not Found: /api/analytics/dashboard/
"GET /api/analytics/dashboard/ HTTP/1.1" 404 6014
Not Found: /api/analytics/dashboard/
"GET /api/analytics/dashboard/ HTTP/1.1" 404 6014
Not Found: /api/analytics/dashboard/
"GET /api/analytics/dashboard/ HTTP/1.1" 404 6014
Not Found: /api/analytics/dashboard/
"GET /api/analytics/dashboard/ HTTP/1.1" 404 6014
"GET /api/analytics/ai/ HTTP/1.1" 200 560
"OPTIONS /auth/login/ HTTP/1.1" 200 0
Unauthorized: /auth/login/
"POST /auth/login/ HTTP/1.1" 401 40
Unauthorized: /auth/login/
"POST /auth/login/ HTTP/1.1" 401 40
"POST /auth/login/ HTTP/1.1" 200 517
"OPTIONS /api/customers/ HTTP/1.1" 200 0
"OPTIONS /api/contracts/ HTTP/1.1" 200 0
"GET /api/contracts/ HTTP/1.1" 200 453
"GET /api/customers/ HTTP/1.1" 200 519
"GET /api/customers/ HTTP/1.1" 200 519
"GET /api/contracts/ HTTP/1.1" 200 453
Not Found: /api/analytics/dashboard/
"GET /api/analytics/dashboard/ HTTP/1.1" 404 6014
"GET /api/contracts/ HTTP/1.1" 200 453
Not Found: /api/analytics/dashboard/
"GET /api/analytics/dashboard/ HTTP/1.1" 404 6014
"OPTIONS /api/analytics/ai/ HTTP/1.1" 200 0
"GET /api/analytics/ai/ HTTP/1.1" 200 560
/app/enterprise_data_system/core/views.py changed, reloading.
Watching for file changes with StatReloader
Not Found: /api/analytics/dashboard/
"GET /api/analytics/dashboard/ HTTP/1.1" 404 6014
"GET /api/contracts/ HTTP/1.1" 200 453
"GET /api/customers/ HTTP/1.1" 200 519
"GET /api/customers/ HTTP/1.1" 200 519
"GET /api/contracts/ HTTP/1.1" 200 453
/app/enterprise_data_system/core/views.py changed, reloading.
Watching for file changes with StatReloader
"GET /api/contracts/ HTTP/1.1" 200 453
Not Found: /api/analytics/dashboard/
"GET /api/analytics/dashboard/ HTTP/1.1" 404 6014
Watching for file changes with StatReloader
Not Found: /api/analytics/dashboard/
"GET /api/analytics/dashboard/ HTTP/1.1" 404 6014
Not Found: /api/analytics/dashboard/
"GET /api/analytics/dashboard/ HTTP/1.1" 404 6014
/app/enterprise_data_system/enterprise_data_system/urls.py changed, reloading.
Watching for file changes with StatReloader
Watching for file changes with StatReloader
"GET /api/analytics/dashboard/ HTTP/1.1" 200 459
"GET /api/analytics/dashboard/ HTTP/1.1" 200 459
"GET /api/contracts/ HTTP/1.1" 200 453
"GET /api/analytics/ai/ HTTP/1.1" 200 560
"GET /api/analytics/ai/ HTTP/1.1" 200 569
"GET /api/analytics/ai/ HTTP/1.1" 200 569
"GET /api/analytics/ai/ HTTP/1.1" 200 569
/app/enterprise_data_system/core/models/customer_models.py changed, reloading.
Watching for file changes with StatReloader
/app/enterprise_data_system/core/models/customer_models.py changed, reloading.
Watching for file changes with StatReloader
Unauthorized: /api/analytics/ai/
"GET /api/analytics/ai/ HTTP/1.1" 401 51
"GET /api/analytics/ai/ HTTP/1.1" 200 584
Unauthorized: /auth/login/
"POST /auth/login/ HTTP/1.1" 401 40
"OPTIONS /auth/login/ HTTP/1.1" 200 0
"POST /auth/login/ HTTP/1.1" 200 517
"GET /api/analytics/ai/ HTTP/1.1" 200 584
"OPTIONS /api/analytics/dashboard/ HTTP/1.1" 200 0
"GET /api/analytics/dashboard/ HTTP/1.1" 200 490
"GET /api/analytics/ai/ HTTP/1.1" 200 584
"GET /api/contracts/ HTTP/1.1" 200 2194
"GET /api/customers/ HTTP/1.1" 200 2726
"GET /api/customers/ HTTP/1.1" 200 2726
"GET /api/contracts/ HTTP/1.1" 200 2194
"GET /api/analytics/dashboard/ HTTP/1.1" 200 490
"GET /api/contracts/ HTTP/1.1" 200 2194
"GET /api/analytics/ai/ HTTP/1.1" 200 584
/app/enterprise_data_system/core/views.py changed, reloading.
Watching for file changes with StatReloader
/app/enterprise_data_system/core/views.py changed, reloading.
Watching for file changes with StatReloader
Watching for file changes with StatReloader
"GET /api/analytics/ai/ HTTP/1.1" 200 392
"GET /api/analytics/ai/ HTTP/1.1" 200 392
"GET /api/analytics/ai/ HTTP/1.1" 200 392
"GET /api/analytics/ai/ HTTP/1.1" 200 392
"OPTIONS /api/customers/ HTTP/1.1" 200 0
"GET /api/customers/ HTTP/1.1" 200 2726
"OPTIONS /api/contracts/ HTTP/1.1" 200 0
"GET /api/contracts/ HTTP/1.1" 200 2194
"GET /api/analytics/dashboard/ HTTP/1.1" 200 490
"GET /api/analytics/ai/ HTTP/1.1" 200 395
Unauthorized: /api/analytics/dashboard/
"GET /api/analytics/dashboard/ HTTP/1.1" 401 51
/app/enterprise_data_system/core/serializers.py changed, reloading.
Watching for file changes with StatReloader
/app/enterprise_data_system/core/serializers.py changed, reloading.
Watching for file changes with StatReloader
/app/enterprise_data_system/core/views.py changed, reloading.
Watching for file changes with StatReloader
/app/enterprise_data_system/enterprise_data_system/urls.py changed, reloading.
Watching for file changes with StatReloader
Watching for file changes with StatReloader
"GET /api/feedbacks/ HTTP/1.1" 200 1950
/app/enterprise_data_system/core/serializers.py changed, reloading.
Watching for file changes with StatReloader
Watching for file changes with StatReloader
"GET /api/feedbacks/ HTTP/1.1" 200 2688
Unauthorized: /auth/login/
"POST /auth/login/ HTTP/1.1" 401 40
Unauthorized: /auth/login/
"POST /auth/login/ HTTP/1.1" 401 40
Unauthorized: /auth/login/
"POST /auth/login/ HTTP/1.1" 401 40
Unauthorized: /auth/login/
"POST /auth/login/ HTTP/1.1" 401 40
Unauthorized: /auth/login/
"POST /auth/login/ HTTP/1.1" 401 40
Unauthorized: /auth/login/
"POST /auth/login/ HTTP/1.1" 401 40
"POST /auth/login/ HTTP/1.1" 200 517
"GET /api/analytics/dashboard/ HTTP/1.1" 200 497
"GET /api/contracts/ HTTP/1.1" 200 2159
"OPTIONS /api/feedbacks/?page=1&page_size=10 HTTP/1.1" 200 0
"GET /api/feedbacks/?page=1&page_size=10 HTTP/1.1" 200 2701
"GET /api/analytics/dashboard/ HTTP/1.1" 200 497
"GET /api/contracts/ HTTP/1.1" 200 2159
"GET /api/customers/ HTTP/1.1" 200 2690
"GET /api/contracts/ HTTP/1.1" 200 2159
"GET /api/customers/ HTTP/1.1" 200 2690
"GET /api/customers/ HTTP/1.1" 200 2690
"GET /api/contracts/ HTTP/1.1" 200 2159
"GET /api/analytics/dashboard/ HTTP/1.1" 200 497
"GET /api/contracts/ HTTP/1.1" 200 2159
"GET /api/customers/ HTTP/1.1" 200 2690
"OPTIONS /api/analytics/dashboard/ HTTP/1.1" 200 0
"GET /api/analytics/dashboard/ HTTP/1.1" 200 497
"GET /api/feedbacks/?page=1&page_size=10 HTTP/1.1" 200 2701
"GET /api/contracts/ HTTP/1.1" 200 2159
"OPTIONS /api/analytics/ai/ HTTP/1.1" 200 0
"GET /api/analytics/ai/ HTTP/1.1" 200 395
